<?xml version="1.0" encoding="utf-8"?>
<!-- =================================================================================== -->
<!-- |    This document was autogenerated by xacro from CartPole.urdf.xacro            | -->
<!-- |    EDITING THIS FILE BY HAND IS NOT RECOMMENDED                                 | -->
<!-- =================================================================================== -->
<robot name="cartpole_xacro">
  <!-- CartPole properties match the OpenAI Gym CartPole-v1 environment -->
  <!-- https://github.com/openai/gym/blob/master/gym/envs/classic_control/cartpole.py -->
  <!-- ====== -->
  <!-- COLORS -->
  <!-- ====== -->
  <material name="black">
    <color rgba="0 0 0 1"/>
  </material>
  <material name="white">
    <color rgba="1 1 1 1"/>
  </material>
  <material name="grey">
    <color rgba="0.2 0.2 0.2 1"/>
  </material>
  <gazebo reference="rail">
    <visual>
      <material>
        <diffuse>0 0 0 1</diffuse>
      </material>
    </visual>
  </gazebo>
  <gazebo reference="cart">
    <visual>
      <material>
        <diffuse>0.2 0.2 0.2 1</diffuse>
      </material>
    </visual>
  </gazebo>
  <gazebo reference="pole">
    <visual>
      <material>
        <diffuse>1 0 0 1</diffuse>
      </material>
    </visual>
  </gazebo>
  <!-- ===== -->
  <!-- LINKS -->
  <!-- ===== -->
  <link name="world"/>
  <link name="rail">
    <inertial>
      <origin rpy="1.57079632679 0 0" xyz="0 0 0"/>
      <mass value="5"/>
      <inertia ixx="10.4166979167" ixy="0" ixz="0" iyy="10.4166979167" iyz="0" izz="6.25e-05"/>
    </inertial>
    <visual>
      <geometry>
        <cylinder length="5" radius="0.005"/>
      </geometry>
      <origin rpy="1.57079632679 0 0" xyz="0 0 0"/>
      <material name="black">
        <color rgba="0 0 0 1"/>
      </material>
    </visual>
  </link>
  <link name="cart">
    <inertial>
      <origin rpy="0 0 0" xyz="0 0 0"/>
      <mass value="1.0"/>
      <inertia ixx="0.00354166666667" ixy="0" ixz="0" iyy="0.00104166666667" iyz="0" izz="0.00416666666667"/>
    </inertial>
    <visual>
      <geometry>
        <box size="0.1 0.2 0.05"/>
      </geometry>
      <origin rpy="0 0 0" xyz="0 0 0"/>
      <material name="grey">
        <color rgba="0.2 0.2 0.2 1"/>
      </material>
    </visual>
    <collision>
      <geometry>
        <box size="0.1 0.2 0.05"/>
      </geometry>
      <origin rpy="0 0 0" xyz="0 0 0"/>
    </collision>
  </link>
  <link name="pole">
    <inertial>
      <origin rpy="0 0 0" xyz="0 0 0.5"/>
      <mass value="0.1"/>
      <inertia ixx="0.00833395833333" ixy="0" ixz="0" iyy="0.00833395833333" iyz="0" izz="1.25e-06"/>
    </inertial>
    <visual>
      <geometry>
        <cylinder length="1.0" radius="0.005"/>
      </geometry>
      <origin rpy="0 0 0" xyz="0 0 0.5"/>
      <material name="red">
        <color rgba="1 0 0 1"/>
      </material>
    </visual>
    <collision>
      <geometry>
        <cylinder length="1.0" radius="0.005"/>
      </geometry>
      <origin rpy="0 0 0" xyz="0 0 0.5"/>
      <material name="red">
        <color rgba="1 0 0 1"/>
      </material>
    </collision>
  </link>
  <!-- ====== -->
  <!-- JOINTS -->
  <!-- ====== -->
  <!--  http://gazebosim.org/tutorials/?tut=ros_urdf#RigidlyFixingAModeltotheWorld-->
  <joint name="world_to_rail" type="fixed">
    <parent link="world"/>
    <child link="rail"/>
    <origin rpy="0 0 0" xyz="0 0 1.2"/>
  </joint>
  <joint name="linear" type="prismatic">
    <parent link="rail"/>
    <child link="cart"/>
    <axis xyz="0 1 0"/>
    <origin rpy="0 0 0" xyz="0 0 0"/>
    <limit effort="500" lower="-2.4" upper="2.4" velocity="10"/>
  </joint>
  <joint name="pivot" type="continuous">
    <parent link="cart"/>
    <child link="pole"/>
    <axis xyz="1 0 0"/>
    <origin rpy="0.0 0 0" xyz="0 0 0.025"/>
    <limit effort="500" lower="-6.28318530718" upper="6.28318530718" velocity="10"/>
  </joint>
</robot>

