<?xml version="1.0" encoding="utf-8"?>
<!-- =================================================================================== -->
<!-- |    This document was autogenerated by xacro from Pendulum.urdf.xacro            | -->
<!-- |    EDITING THIS FILE BY HAND IS NOT RECOMMENDED                                 | -->
<!-- =================================================================================== -->
<robot name="pendulum_xacro">
  <!-- ====== -->
  <!-- COLORS -->
  <!-- ====== -->
  <gazebo reference="pendulum">
    <visual>
      <material>
        <diffuse>1 0 0 1</diffuse>
      </material>
    </visual>
  </gazebo>
  <gazebo reference="pendulum_support">
    <visual>
      <material>
        <diffuse>0.2 0.2 0.2 1</diffuse>
      </material>
    </visual>
  </gazebo>
  <!-- ===== -->
  <!-- LINKS -->
  <!-- ===== -->
  <link name="support">
    <inertial>
      <origin rpy="0 0 0" xyz="0 0 0.3"/>
      <mass value="1000"/>
      <inertia ixx="30.8333333333" ixy="0" ixz="0" iyy="30.2083333333" iyz="0" izz="1.04166666667"/>
    </inertial>
    <visual>
      <geometry>
        <box size="0.05 0.1 0.6"/>
      </geometry>
      <origin rpy="0 0 0" xyz="0 0 0.3"/>
      <material name="black">
        <color rgba="0.2 0.2 0.2 1"/>
      </material>
    </visual>
    <collision>
      <geometry>
        <box size="0.05 0.1 0.6"/>
      </geometry>
      <origin rpy="0 0 0" xyz="0 0 0.3"/>
    </collision>
  </link>
  <link name="pendulum">
    <inertial>
      <origin rpy="0 0 0" xyz="0 0 0.25"/>
      <mass value="1"/>
      <inertia ixx="0.0208583333333" ixy="0" ixz="0" iyy="0.0208583333333" iyz="0" izz="5e-05"/>
    </inertial>
    <visual>
      <geometry>
        <cylinder length="0.5" radius="0.01"/>
      </geometry>
      <origin rpy="0 0 0" xyz="0 0 0.25"/>
      <material name="red">
        <color rgba="1 0 0 1"/>
      </material>
    </visual>
    <visual>
      <geometry>
        <cylinder length="0.02" radius="0.03"/>
      </geometry>
      <origin rpy="0 1.57079632679 0" xyz="0 0 0"/>
      <material name="red">
        <color rgba="1 0 0 1"/>
      </material>
    </visual>
    <collision>
      <geometry>
        <cylinder length="0.5" radius="0.01"/>
      </geometry>
      <origin rpy="0 0 0" xyz="0 0 0.25"/>
    </collision>
  </link>
  <!-- ====== -->
  <!-- JOINTS -->
  <!-- ====== -->
  <joint name="pivot" type="continuous">
    <parent link="support"/>
    <child link="pendulum"/>
    <axis xyz="1 0 0"/>
    <origin rpy="0.0 0 0" xyz="0.035 0 0.57"/>
    <limit effort="500" lower="-6.28318530718" upper="6.28318530718" velocity="10"/>
    <dynamics damping="0" friction="0"/>
  </joint>
</robot>

