<?xml version="1.0" ?>
<!-- =================================================================================== -->
<!-- |    This document was autogenerated by xacro from minitaur_gazebo.urdf.xacro     | -->
<!-- |    EDITING THIS FILE BY HAND IS NOT RECOMMENDED                                 | -->
<!-- =================================================================================== -->
<!-- ======================================================================= -->
<!--LICENSE:                                                                 -->
<!--Copyright (c) 2017, Erwin Coumans                                        -->
<!--Google Inc.                                                              -->
<!--All rights reserved.                                                     -->
<!--                                                                         -->
<!--Redistribution and use in source and binary forms, with or without       -->
<!--modification, are permitted provided that the following conditions are   -->
<!--met:                                                                     -->
<!--                                                                         -->
<!--1. Redistributions or derived work must retain this copyright notice,    -->
<!--   this list of conditions and the following disclaimer.                 -->
<!--                                                                         -->
<!--2. Redistributions in binary form must reproduce the above copyright     -->
<!--   notice, this list of conditions and the following disclaimer in the   -->
<!--   documentation and/or other materials provided with the distribution.  -->
<!--                                                                         -->
<!--THIS SOFTWARE IS PROVIDED BY THE COPYRIGHT HOLDERS AND CONTRIBUTORS "AS  -->
<!--IS" AND ANY EXPRESS OR IMPLIED WARRANTIES, INCLUDING, BUT NOT LIMITED TO,-->
<!--THE IMPLIED WARRANTIES OF MERCHANTABILITY AND FITNESS FOR A PARTICULAR   -->
<!--PURPOSE ARE DISCLAIMED. IN NO EVENT SHALL THE COPYRIGHT HOLDER OR        -->
<!--CONTRIBUTORS BE LIABLE FOR ANY DIRECT, INDIRECT, INCIDENTAL, SPECIAL,    -->
<!--EXEMPLARY, OR CONSEQUENTIAL DAMAGES (INCLUDING, BUT NOT LIMITED TO,      -->
<!--PROCUREMENT OF SUBSTITUTE GOODS OR SERVICES; LOSS OF USE, DATA, OR       -->
<!--PROFITS; OR BUSINESS INTERRUPTION) HOWEVER CAUSED AND ON ANY THEORY OF   -->
<!--LIABILITY, WHETHER IN CONTRACT, STRICT LIABILITY, OR TORT (INCLUDING     -->
<!--NEGLIGENCE OR OTHERWISE) ARISING IN ANY WAY OUT OF THE USE OF THIS       -->
<!--SOFTWARE, EVEN IF ADVISED OF THE POSSIBILITY OF SUCH DAMAGE.             -->
<!--                                                                         -->
<!-- Converted to xacro by Tom Jacobs and Vasileios Vasilopoulos             -->
<!-- <tom.jacobs@ghostrobotics.io>, <v.vasilo@ghostrobotics.io>              -->
<robot name="minitaur" xmlns:xacro="http://www.ros.org/wiki/xacro">
  <!-- Define parameters -->
  <!-- 7.18kg minitaur total weight - 0.016*4 - 0.10*8 - 0.25*8 - 0.05*8 - 0.05*8 = 3.516 -->
  <!-- * 4 frames -->
  <!-- * 8 motor modules -->
  <!-- * 8 motors -->
  <!-- * 8 upper legs -->
  <!-- * 8 lower legs -->
  <!-- LINK: Body dummy -->
  <link name="base_chassis_link_dummy">
    <visual>
      <geometry>
        <box size="0.33 0.1855 0.08"/>
      </geometry>
    </visual>
    <visual>
      <origin rpy="0 0 0" xyz="0 0.10 -0.014"/>
      <geometry>
        <box size="0.17 0.1 0.05"/>
      </geometry>
    </visual>
    <visual>
      <origin rpy="0 0 0" xyz="0 -0.10 -0.014"/>
      <geometry>
        <box size="0.17 0.1 0.05"/>
      </geometry>
    </visual>
    <collision>
      <geometry>
        <box size="0.33 0.1855 0.08"/>
      </geometry>
    </collision>
    <collision>
      <origin rpy="0 0 0" xyz="0 0.10 -0.014"/>
      <geometry>
        <box size="0.17 0.1 0.05"/>
      </geometry>
    </collision>
    <collision>
      <origin rpy="0 0 0" xyz="0 -0.10 -0.014"/>
      <geometry>
        <box size="0.17 0.1 0.05"/>
      </geometry>
    </collision>
  </link>
  <gazebo reference="base_chassis_link_dummy">
    <material>Gazebo/FlatBlack</material>
  </gazebo>
  <!-- LINK: Body -->
  <link name="base_chassis_link">
    <visual>
      <geometry>
        <box size="0.33 0.1855 0.08"/>
      </geometry>
    </visual>
    <visual>
      <origin rpy="0 0 0" xyz="0 0.10 -0.014"/>
      <geometry>
        <box size="0.17 0.1 0.05"/>
      </geometry>
    </visual>
    <visual>
      <origin rpy="0 0 0" xyz="0 -0.10 -0.014"/>
      <geometry>
        <box size="0.17 0.1 0.05"/>
      </geometry>
    </visual>
    <collision>
      <geometry>
        <box size="0.33 0.1855 0.08"/>
      </geometry>
    </collision>
    <collision>
      <origin rpy="0 0 0" xyz="0 0.10 -0.014"/>
      <geometry>
        <box size="0.17 0.1 0.05"/>
      </geometry>
    </collision>
    <collision>
      <origin rpy="0 0 0" xyz="0 -0.10 -0.014"/>
      <geometry>
        <box size="0.17 0.1 0.05"/>
      </geometry>
    </collision>
    <inertial>
      <mass value="3.516"/>
      <origin rpy="0 0 0" xyz="0 0 0"/>
      <!-- https://en.wikipedia.org/wiki/List_of_moments_of_inertia Solid Cuboid -->
      <inertia ixx="0.01195740325" ixy="0.0" ixz="0.0" iyy="0.0337829" iyz="0.0" izz="0.04198990325"/>
    </inertial>
  </link>
  <gazebo reference="base_chassis_link">
    <material>Gazebo/FlatBlack</material>
  </gazebo>
  <!-- JOINT: body to body dummy -->
  <joint name="dummy_joint" type="fixed">
    <axis xyz="0 0 1"/>
    <parent link="base_chassis_link_dummy"/>
    <child link="base_chassis_link"/>
    <origin rpy="0 0 0" xyz="0 0 0"/>
    <limit effort="100" velocity="100"/>
    <joint_properties damping=".0" friction=".0"/>
  </joint>
  <!-- LINK: frame1 -->
  <link name="frame1">
    <visual>
      <origin rpy="0 0 0" xyz="-0.22 0 0"/>
      <geometry>
        <box size="0.468 .012 .050"/>
      </geometry>
    </visual>
    <collision>
      <origin rpy="0 0 0" xyz="-0.22 0 0"/>
      <geometry>
        <box size="0.468 .012 .050"/>
      </geometry>
    </collision>
    <inertial>
      <origin rpy="0 0 0" xyz="0 -0.03 0"/>
      <mass value="0.16"/>
      <inertia ixx=".00011397" ixy=".0" ixz=".0" iyy=".00011397" iyz=".0" izz=".00021765"/>
    </inertial>
  </link>
  <gazebo reference="frame1">
    <material>Gazebo/Grey</material>
  </gazebo>
  <!-- JOINT: frame1 to body -->
  <joint name="frame1_joint" type="fixed">
    <axis xyz="0 0 1"/>
    <parent link="base_chassis_link"/>
    <child link="frame1"/>
    <origin rpy="0 0 0" xyz=".2375 -0.154 -.0185"/>
    <limit effort="100" velocity="100"/>
    <joint_properties damping=".0" friction=".0"/>
  </joint>
  <!-- LINK: frame2 -->
  <link name="frame2">
    <visual>
      <origin rpy="0 0 0" xyz="-0.22 0 0"/>
      <geometry>
        <box size="0.468 .012 .050"/>
      </geometry>
    </visual>
    <collision>
      <origin rpy="0 0 0" xyz="-0.22 0 0"/>
      <geometry>
        <box size="0.468 .012 .050"/>
      </geometry>
    </collision>
    <inertial>
      <origin rpy="0 0 0" xyz="0 0.02 0"/>
      <mass value="0.16"/>
      <inertia ixx=".00011397" ixy=".0" ixz=".0" iyy=".00011397" iyz=".0" izz=".00021765"/>
    </inertial>
  </link>
  <gazebo reference="frame2">
    <material>Gazebo/Grey</material>
  </gazebo>
  <!-- JOINT: frame2 to body -->
  <joint name="frame2_joint" type="fixed">
    <axis xyz="0 0 1"/>
    <parent link="base_chassis_link"/>
    <child link="frame2"/>
    <origin rpy="0 0 0" xyz=".2375 0.154 -.0185"/>
    <limit effort="100" velocity="100"/>
    <joint_properties damping=".0" friction=".0"/>
  </joint>
  <!-- LINK: frame3 -->
  <link name="frame3">
    <visual>
      <origin rpy="0 0 0" xyz="0.22 0.055 0"/>
      <geometry>
        <box size="0.468 .012 .050"/>
      </geometry>
    </visual>
    <collision>
      <origin rpy="0 0 0" xyz="0.22 0.055 0"/>
      <geometry>
        <box size="0.468 .012 .050"/>
      </geometry>
    </collision>
    <inertial>
      <origin rpy="0 0 0" xyz="0 -0.03 0"/>
      <mass value="0.16"/>
      <inertia ixx=".00011397" ixy=".0" ixz=".0" iyy=".00011397" iyz=".0" izz=".00021765"/>
    </inertial>
  </link>
  <gazebo reference="frame3">
    <material>Gazebo/Grey</material>
  </gazebo>
  <!-- JOINT: frame3 to body -->
  <joint name="frame3_joint" type="fixed">
    <axis xyz="0 0 1"/>
    <parent link="base_chassis_link"/>
    <child link="frame3"/>
    <origin rpy="0 0 0" xyz="-.2375 -0.154 -.0185"/>
    <limit effort="100" velocity="100"/>
    <joint_properties damping=".0" friction=".0"/>
  </joint>
  <!-- LINK: frame4 -->
  <link name="frame4">
    <visual>
      <origin rpy="0 0 0" xyz="0.22 -0.055 0"/>
      <geometry>
        <box size="0.468 .012 .050"/>
      </geometry>
    </visual>
    <collision>
      <origin rpy="0 0 0" xyz="0.22 -0.055 0"/>
      <geometry>
        <box size="0.468 .012 .050"/>
      </geometry>
    </collision>
    <inertial>
      <origin rpy="0 0 0" xyz="0 0.02 0"/>
      <mass value="0.16"/>
      <inertia ixx=".00011397" ixy=".0" ixz=".0" iyy=".00011397" iyz=".0" izz=".00021765"/>
    </inertial>
  </link>
  <gazebo reference="frame4">
    <material>Gazebo/Grey</material>
  </gazebo>
  <!-- JOINT: frame4 to body -->
  <joint name="frame4" type="fixed">
    <axis xyz="0 0 1"/>
    <parent link="base_chassis_link"/>
    <child link="frame4"/>
    <origin rpy="0 0 0" xyz="-.2375 0.154 -.0185"/>
    <limit effort="100" velocity="100"/>
    <joint_properties damping=".0" friction=".0"/>
  </joint>
  <!-- Inside motor module boxes -->
  <!-- LINK: chassis_right -->
  <link name="chassis_right">
    <visual>
      <origin rpy="0 0 0" xyz=".2375 .049 0"/>
      <geometry>
        <box size=".068 .032 .050"/>
      </geometry>
    </visual>
    <visual>
      <origin rpy="0 0 0" xyz="-.2375 .049 0"/>
      <geometry>
        <box size=".068 .032 .050"/>
      </geometry>
    </visual>
    <collision>
      <origin rpy="0 0 0" xyz=".2375 .049 0"/>
      <geometry>
        <box size=".068 .032 .050"/>
      </geometry>
    </collision>
    <collision>
      <origin rpy="0 0 0" xyz="-.2375 .049 0"/>
      <geometry>
        <box size=".068 .032 .050"/>
      </geometry>
    </collision>
    <inertial>
      <mass value="0.2"/>
      <inertia ixx=".004147" ixy=".0" ixz=".0" iyy=".040913" iyz=".0" izz=".041840"/>
    </inertial>
  </link>
  <gazebo reference="chassis_right">
    <material>Gazebo/Black</material>
  </gazebo>
  <!-- JOINT: chassis_right_center to body -->
  <joint name="chassis_right_center" type="fixed">
    <axis xyz="0 0 1"/>
    <parent link="base_chassis_link"/>
    <child link="chassis_right"/>
    <origin rpy="0 0 0" xyz="0 -.1265 -.0185"/>
    <limit effort="100" velocity="100"/>
    <joint_properties damping=".0" friction=".0"/>
  </joint>
  <!-- LINK: chassis_left -->
  <link name="chassis_left">
    <visual>
      <origin rpy="0 0 0" xyz=".2375 -.049 0"/>
      <geometry>
        <box size=".068 .032 .050"/>
      </geometry>
    </visual>
    <visual>
      <origin rpy="0 0 0" xyz="-.2375 -.049 0"/>
      <geometry>
        <box size=".068 .032 .050"/>
      </geometry>
    </visual>
    <collision>
      <origin rpy="0 0 0" xyz=".2375 -.049 0"/>
      <geometry>
        <box size=".068 .032 .050"/>
      </geometry>
    </collision>
    <collision>
      <origin rpy="0 0 0" xyz="-.2375 -.049 0"/>
      <geometry>
        <box size=".068 .032 .050"/>
      </geometry>
    </collision>
    <inertial>
      <mass value="0.2"/>
      <inertia ixx=".004147" ixy=".0" ixz=".0" iyy=".040913" iyz=".0" izz=".041840"/>
    </inertial>
  </link>
  <gazebo reference="chassis_left">
    <material>Gazebo/Black</material>
  </gazebo>
  <!-- JOINT: chassis_left_center to body -->
  <joint name="chassis_left_center" type="fixed">
    <axis xyz="0 0 1"/>
    <parent link="base_chassis_link"/>
    <child link="chassis_left"/>
    <origin rpy="0 0 0" xyz="0 .1265 -.0185"/>
    <limit effort="100" velocity="100"/>
    <joint_properties damping=".0" friction=".0"/>
  </joint>
  <!-- Outside motor module boxes -->
  <!-- LINK: motor_front_rightR_bracket_link -->
  <link name="motor_front_rightR_bracket_link">
    <visual>
      <origin rpy="0 0 0" xyz="0 -0.02 0"/>
      <geometry>
        <box size="0.068 .032 .050"/>
      </geometry>
    </visual>
    <collision>
      <origin rpy="0 0 0" xyz="0 -0.02 0"/>
      <geometry>
        <box size=".068 .032 .050"/>
      </geometry>
    </collision>
    <inertial>
      <origin rpy="0 0 0" xyz="0 -0.03 0"/>
      <mass value="0.1"/>
      <inertia ixx=".00011397" ixy=".0" ixz=".0" iyy=".00011397" iyz=".0" izz=".00021765"/>
    </inertial>
  </link>
  <gazebo reference="motor_front_rightR_bracket_link">
    <material>Gazebo/Black</material>
  </gazebo>
  <!-- JOINT: motor_front_rightR_bracket_link to body -->
  <joint name="motor_front_rightR_bracket_joint" type="fixed">
    <axis xyz="0 0 1"/>
    <parent link="base_chassis_link"/>
    <child link="motor_front_rightR_bracket_link"/>
    <origin rpy="0 0 0" xyz=".2375 -0.154 -.0185"/>
    <limit effort="100" velocity="100"/>
    <joint_properties damping=".0" friction=".0"/>
  </joint>
  <!-- LINK: motor_front_leftL_bracket_link -->
  <link name="motor_front_leftL_bracket_link">
    <visual>
      <origin rpy="0 0 0" xyz="0 0.02 0"/>
      <geometry>
        <box size="0.068 .032 .050"/>
      </geometry>
    </visual>
    <collision>
      <origin rpy="0 0 0" xyz="0 0.02 0"/>
      <geometry>
        <box size=".068 .032 .050"/>
      </geometry>
    </collision>
    <inertial>
      <origin rpy="0 0 0" xyz="0 0.02 0"/>
      <mass value="0.1"/>
      <inertia ixx=".00011397" ixy=".0" ixz=".0" iyy=".00011397" iyz=".0" izz=".00021765"/>
    </inertial>
  </link>
  <gazebo reference="motor_front_leftL_bracket_link">
    <material>Gazebo/Black</material>
  </gazebo>
  <!-- JOINT: motor_front_leftL_bracket_joint to body -->
  <joint name="motor_front_leftL_bracket_joint" type="fixed">
    <axis xyz="0 0 1"/>
    <parent link="base_chassis_link"/>
    <child link="motor_front_leftL_bracket_link"/>
    <origin rpy="0 0 0" xyz=".2375 0.154 -.0185"/>
    <limit effort="100" velocity="100"/>
    <joint_properties damping=".0" friction=".0"/>
  </joint>
  <!-- LINK: motor_back_rightR_bracket_link -->
  <link name="motor_back_rightR_bracket_link">
    <visual>
      <origin rpy="0 0 0" xyz="0 -0.02 0"/>
      <geometry>
        <box size="0.068 .032 .050"/>
      </geometry>
    </visual>
    <collision>
      <origin rpy="0 0 0" xyz="0 -0.02 0"/>
      <geometry>
        <box size=".068 .032 .050"/>
      </geometry>
    </collision>
    <inertial>
      <origin rpy="0 0 0" xyz="0 -0.03 0"/>
      <mass value="0.1"/>
      <inertia ixx=".00011397" ixy=".0" ixz=".0" iyy=".00011397" iyz=".0" izz=".00021765"/>
    </inertial>
  </link>
  <gazebo reference="motor_back_rightR_bracket_link">
    <material>Gazebo/Black</material>
  </gazebo>
  <!-- JOINT: motor_back_rightR_bracket_joint to body -->
  <joint name="motor_back_rightR_bracket_joint" type="fixed">
    <axis xyz="0 0 1"/>
    <parent link="base_chassis_link"/>
    <child link="motor_back_rightR_bracket_link"/>
    <origin rpy="0 0 0" xyz="-.2375 -0.154 -.0185"/>
    <limit effort="100" velocity="100"/>
    <joint_properties damping=".0" friction=".0"/>
  </joint>
  <!-- LINK: motor_back_leftL_bracket_link -->
  <link name="motor_back_leftL_bracket_link">
    <visual>
      <origin rpy="0 0 0" xyz="0 0.02 0"/>
      <geometry>
        <box size="0.068 .032 .050"/>
      </geometry>
    </visual>
    <collision>
      <origin rpy="0 0 0" xyz="0 0.02 0"/>
      <geometry>
        <box size=".068 .032 .050"/>
      </geometry>
    </collision>
    <inertial>
      <origin rpy="0 0 0" xyz="0 0.02 0"/>
      <mass value="0.1"/>
      <inertia ixx=".00011397" ixy=".0" ixz=".0" iyy=".00011397" iyz=".0" izz=".00021765"/>
    </inertial>
  </link>
  <gazebo reference="motor_back_leftL_bracket_link">
    <material>Gazebo/Black</material>
  </gazebo>
  <!-- JOINT: motor_back_leftL_bracket_joint to body -->
  <joint name="motor_back_leftL_bracket_joint" type="fixed">
    <axis xyz="0 0 1"/>
    <parent link="base_chassis_link"/>
    <child link="motor_back_leftL_bracket_link"/>
    <origin rpy="0 0 0" xyz="-.2375 0.154 -.0185"/>
    <limit effort="100" velocity="100"/>
    <joint_properties damping=".0" friction=".0"/>
  </joint>
  <!-- Define our motor macro -->
  <!-- Motors -->
  <!-- LINK: motor_${location}_${side}${LR}_link -->
  <link name="motor_front_rightR_link">
    <visual>
      <geometry>
        <mesh filename="package://GymIgnition/models/Minitaur/meshes/tmotor3.dae" scale="100 100 100"/>
      </geometry>
    </visual>
    <collision>
      <geometry>
        <cylinder length="0.021" radius="0.0425"/>
      </geometry>
    </collision>
    <inertial>
      <mass value="0.25"/>
      <inertia ixx=".00011397" ixy=".0" ixz=".0" iyy=".00011397" iyz=".0" izz=".00021765"/>
    </inertial>
  </link>
  <!-- JOINT: motor_${location}_${side}${LR}_link to ${chassis} -->
  <joint name="5" type="continuous">
    <axis xyz="0 0 1"/>
    <parent link="motor_front_rightR_bracket_link"/>
    <child link="motor_front_rightR_link"/>
    <origin rpy="1.57075 -1.57075 0" xyz="0 0 0"/>
    <limit effort="100" velocity="100"/>
    <joint_properties damping="0.0" friction="0.0"/>
  </joint>
  <!-- Transmission elements required for Gazebo -->
  <transmission name="transmission_5">
    <type>transmission_interface/SimpleTransmission</type>
    <joint name="5">
      <hardwareInterface>hardware_interface/EffortJointInterface</hardwareInterface>
    </joint>
    <actuator name="motor_5">
      <hardwareInterface>EffortJointInterface</hardwareInterface>
      <mechanicalReduction>1</mechanicalReduction>
    </actuator>
  </transmission>
  <!-- LINK: motor_${location}_${side}${LR}_link -->
  <link name="motor_front_rightL_link">
    <visual>
      <geometry>
        <mesh filename="package://GymIgnition/models/Minitaur/meshes/tmotor3.dae" scale="100 100 100"/>
      </geometry>
    </visual>
    <collision>
      <geometry>
        <cylinder length="0.021" radius="0.0425"/>
      </geometry>
    </collision>
    <inertial>
      <mass value="0.25"/>
      <inertia ixx=".00011397" ixy=".0" ixz=".0" iyy=".00011397" iyz=".0" izz=".00021765"/>
    </inertial>
  </link>
  <!-- JOINT: motor_${location}_${side}${LR}_link to ${chassis} -->
  <joint name="4" type="continuous">
    <axis xyz="0 0 -1"/>
    <parent link="chassis_right"/>
    <child link="motor_front_rightL_link"/>
    <origin rpy="1.57075 1.57075 0" xyz=".2375 .0275 0"/>
    <limit effort="100" velocity="100"/>
    <joint_properties damping="0.0" friction="0.0"/>
  </joint>
  <!-- Transmission elements required for Gazebo -->
  <transmission name="transmission_4">
    <type>transmission_interface/SimpleTransmission</type>
    <joint name="4">
      <hardwareInterface>hardware_interface/EffortJointInterface</hardwareInterface>
    </joint>
    <actuator name="motor_4">
      <hardwareInterface>EffortJointInterface</hardwareInterface>
      <mechanicalReduction>1</mechanicalReduction>
    </actuator>
  </transmission>
  <!-- LINK: motor_${location}_${side}${LR}_link -->
  <link name="motor_front_leftL_link">
    <visual>
      <geometry>
        <mesh filename="package://GymIgnition/models/Minitaur/meshes/tmotor3.dae" scale="100 100 100"/>
      </geometry>
    </visual>
    <collision>
      <geometry>
        <cylinder length="0.021" radius="0.0425"/>
      </geometry>
    </collision>
    <inertial>
      <mass value="0.25"/>
      <inertia ixx=".00011397" ixy=".0" ixz=".0" iyy=".00011397" iyz=".0" izz=".00021765"/>
    </inertial>
  </link>
  <!-- JOINT: motor_${location}_${side}${LR}_link to ${chassis} -->
  <joint name="0" type="continuous">
    <axis xyz="0 0 -1"/>
    <parent link="motor_front_leftL_bracket_link"/>
    <child link="motor_front_leftL_link"/>
    <origin rpy="1.57075 -1.57075 0" xyz="0 0 0"/>
    <limit effort="100" velocity="100"/>
    <joint_properties damping="0.0" friction="0.0"/>
  </joint>
  <!-- Transmission elements required for Gazebo -->
  <transmission name="transmission_0">
    <type>transmission_interface/SimpleTransmission</type>
    <joint name="0">
      <hardwareInterface>hardware_interface/EffortJointInterface</hardwareInterface>
    </joint>
    <actuator name="motor_0">
      <hardwareInterface>EffortJointInterface</hardwareInterface>
      <mechanicalReduction>1</mechanicalReduction>
    </actuator>
  </transmission>
  <!-- LINK: motor_${location}_${side}${LR}_link -->
  <link name="motor_front_leftR_link">
    <visual>
      <geometry>
        <mesh filename="package://GymIgnition/models/Minitaur/meshes/tmotor3.dae" scale="100 100 100"/>
      </geometry>
    </visual>
    <collision>
      <geometry>
        <cylinder length="0.021" radius="0.0425"/>
      </geometry>
    </collision>
    <inertial>
      <mass value="0.25"/>
      <inertia ixx=".00011397" ixy=".0" ixz=".0" iyy=".00011397" iyz=".0" izz=".00021765"/>
    </inertial>
  </link>
  <!-- JOINT: motor_${location}_${side}${LR}_link to ${chassis} -->
  <joint name="1" type="continuous">
    <axis xyz="0 0 1"/>
    <parent link="chassis_left"/>
    <child link="motor_front_leftR_link"/>
    <origin rpy="1.57075 1.57075 0" xyz=".2375 -.0275 0"/>
    <limit effort="100" velocity="100"/>
    <joint_properties damping="0.0" friction="0.0"/>
  </joint>
  <!-- Transmission elements required for Gazebo -->
  <transmission name="transmission_1">
    <type>transmission_interface/SimpleTransmission</type>
    <joint name="1">
      <hardwareInterface>hardware_interface/EffortJointInterface</hardwareInterface>
    </joint>
    <actuator name="motor_1">
      <hardwareInterface>EffortJointInterface</hardwareInterface>
      <mechanicalReduction>1</mechanicalReduction>
    </actuator>
  </transmission>
  <!-- LINK: motor_${location}_${side}${LR}_link -->
  <link name="motor_back_rightR_link">
    <visual>
      <geometry>
        <mesh filename="package://GymIgnition/models/Minitaur/meshes/tmotor3.dae" scale="100 100 100"/>
      </geometry>
    </visual>
    <collision>
      <geometry>
        <cylinder length="0.021" radius="0.0425"/>
      </geometry>
    </collision>
    <inertial>
      <mass value="0.25"/>
      <inertia ixx=".00011397" ixy=".0" ixz=".0" iyy=".00011397" iyz=".0" izz=".00021765"/>
    </inertial>
  </link>
  <!-- JOINT: motor_${location}_${side}${LR}_link to ${chassis} -->
  <joint name="7" type="continuous">
    <axis xyz="0 0 1"/>
    <parent link="motor_back_rightR_bracket_link"/>
    <child link="motor_back_rightR_link"/>
    <origin rpy="1.57075 -1.57075 0" xyz="0 0 0"/>
    <limit effort="100" velocity="100"/>
    <joint_properties damping="0.0" friction="0.0"/>
  </joint>
  <!-- Transmission elements required for Gazebo -->
  <transmission name="transmission_7">
    <type>transmission_interface/SimpleTransmission</type>
    <joint name="7">
      <hardwareInterface>hardware_interface/EffortJointInterface</hardwareInterface>
    </joint>
    <actuator name="motor_7">
      <hardwareInterface>EffortJointInterface</hardwareInterface>
      <mechanicalReduction>1</mechanicalReduction>
    </actuator>
  </transmission>
  <!-- LINK: motor_${location}_${side}${LR}_link -->
  <link name="motor_back_rightL_link">
    <visual>
      <geometry>
        <mesh filename="package://GymIgnition/models/Minitaur/meshes/tmotor3.dae" scale="100 100 100"/>
      </geometry>
    </visual>
    <collision>
      <geometry>
        <cylinder length="0.021" radius="0.0425"/>
      </geometry>
    </collision>
    <inertial>
      <mass value="0.25"/>
      <inertia ixx=".00011397" ixy=".0" ixz=".0" iyy=".00011397" iyz=".0" izz=".00021765"/>
    </inertial>
  </link>
  <!-- JOINT: motor_${location}_${side}${LR}_link to ${chassis} -->
  <joint name="6" type="continuous">
    <axis xyz="0 0 -1"/>
    <parent link="chassis_right"/>
    <child link="motor_back_rightL_link"/>
    <origin rpy="1.57075 1.57075 0" xyz="-.2375 .0275 0"/>
    <limit effort="100" velocity="100"/>
    <joint_properties damping="0.0" friction="0.0"/>
  </joint>
  <!-- Transmission elements required for Gazebo -->
  <transmission name="transmission_6">
    <type>transmission_interface/SimpleTransmission</type>
    <joint name="6">
      <hardwareInterface>hardware_interface/EffortJointInterface</hardwareInterface>
    </joint>
    <actuator name="motor_6">
      <hardwareInterface>EffortJointInterface</hardwareInterface>
      <mechanicalReduction>1</mechanicalReduction>
    </actuator>
  </transmission>
  <!-- LINK: motor_${location}_${side}${LR}_link -->
  <link name="motor_back_leftL_link">
    <visual>
      <geometry>
        <mesh filename="package://GymIgnition/models/Minitaur/meshes/tmotor3.dae" scale="100 100 100"/>
      </geometry>
    </visual>
    <collision>
      <geometry>
        <cylinder length="0.021" radius="0.0425"/>
      </geometry>
    </collision>
    <inertial>
      <mass value="0.25"/>
      <inertia ixx=".00011397" ixy=".0" ixz=".0" iyy=".00011397" iyz=".0" izz=".00021765"/>
    </inertial>
  </link>
  <!-- JOINT: motor_${location}_${side}${LR}_link to ${chassis} -->
  <joint name="2" type="continuous">
    <axis xyz="0 0 -1"/>
    <parent link="motor_back_leftL_bracket_link"/>
    <child link="motor_back_leftL_link"/>
    <origin rpy="1.57075 -1.57075 0" xyz="0 0 0"/>
    <limit effort="100" velocity="100"/>
    <joint_properties damping="0.0" friction="0.0"/>
  </joint>
  <!-- Transmission elements required for Gazebo -->
  <transmission name="transmission_2">
    <type>transmission_interface/SimpleTransmission</type>
    <joint name="2">
      <hardwareInterface>hardware_interface/EffortJointInterface</hardwareInterface>
    </joint>
    <actuator name="motor_2">
      <hardwareInterface>EffortJointInterface</hardwareInterface>
      <mechanicalReduction>1</mechanicalReduction>
    </actuator>
  </transmission>
  <!-- LINK: motor_${location}_${side}${LR}_link -->
  <link name="motor_back_leftR_link">
    <visual>
      <geometry>
        <mesh filename="package://GymIgnition/models/Minitaur/meshes/tmotor3.dae" scale="100 100 100"/>
      </geometry>
    </visual>
    <collision>
      <geometry>
        <cylinder length="0.021" radius="0.0425"/>
      </geometry>
    </collision>
    <inertial>
      <mass value="0.25"/>
      <inertia ixx=".00011397" ixy=".0" ixz=".0" iyy=".00011397" iyz=".0" izz=".00021765"/>
    </inertial>
  </link>
  <!-- JOINT: motor_${location}_${side}${LR}_link to ${chassis} -->
  <joint name="3" type="continuous">
    <axis xyz="0 0 1"/>
    <parent link="chassis_left"/>
    <child link="motor_back_leftR_link"/>
    <origin rpy="1.57075 1.57075 0" xyz="-.2375 -.0275 0"/>
    <limit effort="100" velocity="100"/>
    <joint_properties damping="0.0" friction="0.0"/>
  </joint>
  <!-- Transmission elements required for Gazebo -->
  <transmission name="transmission_3">
    <type>transmission_interface/SimpleTransmission</type>
    <joint name="3">
      <hardwareInterface>hardware_interface/EffortJointInterface</hardwareInterface>
    </joint>
    <actuator name="motor_3">
      <hardwareInterface>EffortJointInterface</hardwareInterface>
      <mechanicalReduction>1</mechanicalReduction>
    </actuator>
  </transmission>
  <!-- Define our upper leg macro -->
  <!-- Define our lower leg macro -->
  <!-- Legs -->
  <!-- LINK: upper_leg_${location}_link -->
  <link name="upper_leg_front_rightR_link">
    <visual>
      <geometry>
        <box size="0.039 0.008 0.1"/>
      </geometry>
    </visual>
    <collision>
      <geometry>
        <box size="0.039 0.008 0.1"/>
      </geometry>
    </collision>
    <inertial>
      <mass value="0.05"/>
      <inertia ixx=".000038770" ixy=".0" ixz=".0" iyy=".000042198" iyz=".0" izz=".0000036030"/>
    </inertial>
  </link>
  <gazebo reference="upper_leg_front_rightR_link">
    <material>Gazebo/Grey</material>
  </gazebo>
  <!-- JOINT: ${hip}_${location}_link to motor_${location}_link -->
  <joint name="hip_front_rightR_link" type="fixed">
    <axis xyz="0 0 1"/>
    <parent link="motor_front_rightR_link"/>
    <child link="upper_leg_front_rightR_link"/>
    <origin rpy="-1.57075 0 0" xyz="0 .045 -.0145"/>
    <limit effort="100" velocity="100"/>
    <joint_properties damping="0.0" friction="0.0"/>
  </joint>
  <!-- LINK: upper_leg_${location}_link -->
  <link name="upper_leg_front_rightL_link">
    <visual>
      <geometry>
        <box size="0.039 0.008 0.1"/>
      </geometry>
    </visual>
    <collision>
      <geometry>
        <box size="0.039 0.008 0.1"/>
      </geometry>
    </collision>
    <inertial>
      <mass value="0.05"/>
      <inertia ixx=".000038770" ixy=".0" ixz=".0" iyy=".000042198" iyz=".0" izz=".0000036030"/>
    </inertial>
  </link>
  <gazebo reference="upper_leg_front_rightL_link">
    <material>Gazebo/Grey</material>
  </gazebo>
  <!-- JOINT: ${hip}_${location}_link to motor_${location}_link -->
  <joint name="motor_front_rightL_link" type="fixed">
    <axis xyz="0 0 1"/>
    <parent link="motor_front_rightL_link"/>
    <child link="upper_leg_front_rightL_link"/>
    <origin rpy="-1.57075 0 0" xyz="0 .045 .0145"/>
    <limit effort="100" velocity="100"/>
    <joint_properties damping="0.0" friction="0.0"/>
  </joint>
  <!-- LINK: upper_leg_${location}_link -->
  <link name="upper_leg_front_leftR_link">
    <visual>
      <geometry>
        <box size="0.039 0.008 0.1"/>
      </geometry>
    </visual>
    <collision>
      <geometry>
        <box size="0.039 0.008 0.1"/>
      </geometry>
    </collision>
    <inertial>
      <mass value="0.05"/>
      <inertia ixx=".000038770" ixy=".0" ixz=".0" iyy=".000042198" iyz=".0" izz=".0000036030"/>
    </inertial>
  </link>
  <gazebo reference="upper_leg_front_leftR_link">
    <material>Gazebo/Grey</material>
  </gazebo>
  <!-- JOINT: ${hip}_${location}_link to motor_${location}_link -->
  <joint name="hip_front_leftR_link" type="fixed">
    <axis xyz="0 0 1"/>
    <parent link="motor_front_leftR_link"/>
    <child link="upper_leg_front_leftR_link"/>
    <origin rpy="-1.57075 0 0" xyz="0 .045 -.0145"/>
    <limit effort="100" velocity="100"/>
    <joint_properties damping="0.0" friction="0.0"/>
  </joint>
  <!-- LINK: upper_leg_${location}_link -->
  <link name="upper_leg_front_leftL_link">
    <visual>
      <geometry>
        <box size="0.039 0.008 0.1"/>
      </geometry>
    </visual>
    <collision>
      <geometry>
        <box size="0.039 0.008 0.1"/>
      </geometry>
    </collision>
    <inertial>
      <mass value="0.05"/>
      <inertia ixx=".000038770" ixy=".0" ixz=".0" iyy=".000042198" iyz=".0" izz=".0000036030"/>
    </inertial>
  </link>
  <gazebo reference="upper_leg_front_leftL_link">
    <material>Gazebo/Grey</material>
  </gazebo>
  <!-- JOINT: ${hip}_${location}_link to motor_${location}_link -->
  <joint name="motor_front_leftL_link" type="fixed">
    <axis xyz="0 0 1"/>
    <parent link="motor_front_leftL_link"/>
    <child link="upper_leg_front_leftL_link"/>
    <origin rpy="-1.57075 0 0" xyz="0 .045 .0145"/>
    <limit effort="100" velocity="100"/>
    <joint_properties damping="0.0" friction="0.0"/>
  </joint>
  <!-- LINK: upper_leg_${location}_link -->
  <link name="upper_leg_back_rightR_link">
    <visual>
      <geometry>
        <box size="0.039 0.008 0.1"/>
      </geometry>
    </visual>
    <collision>
      <geometry>
        <box size="0.039 0.008 0.1"/>
      </geometry>
    </collision>
    <inertial>
      <mass value="0.05"/>
      <inertia ixx=".000038770" ixy=".0" ixz=".0" iyy=".000042198" iyz=".0" izz=".0000036030"/>
    </inertial>
  </link>
  <gazebo reference="upper_leg_back_rightR_link">
    <material>Gazebo/Grey</material>
  </gazebo>
  <!-- JOINT: ${hip}_${location}_link to motor_${location}_link -->
  <joint name="hip_back_rightR_link" type="fixed">
    <axis xyz="0 0 1"/>
    <parent link="motor_back_rightR_link"/>
    <child link="upper_leg_back_rightR_link"/>
    <origin rpy="-1.57075 0 0" xyz="0 .045 -.0145"/>
    <limit effort="100" velocity="100"/>
    <joint_properties damping="0.0" friction="0.0"/>
  </joint>
  <!-- LINK: upper_leg_${location}_link -->
  <link name="upper_leg_back_rightL_link">
    <visual>
      <geometry>
        <box size="0.039 0.008 0.1"/>
      </geometry>
    </visual>
    <collision>
      <geometry>
        <box size="0.039 0.008 0.1"/>
      </geometry>
    </collision>
    <inertial>
      <mass value="0.05"/>
      <inertia ixx=".000038770" ixy=".0" ixz=".0" iyy=".000042198" iyz=".0" izz=".0000036030"/>
    </inertial>
  </link>
  <gazebo reference="upper_leg_back_rightL_link">
    <material>Gazebo/Grey</material>
  </gazebo>
  <!-- JOINT: ${hip}_${location}_link to motor_${location}_link -->
  <joint name="motor_back_rightL_link" type="fixed">
    <axis xyz="0 0 1"/>
    <parent link="motor_back_rightL_link"/>
    <child link="upper_leg_back_rightL_link"/>
    <origin rpy="-1.57075 0 0" xyz="0 .045 .0145"/>
    <limit effort="100" velocity="100"/>
    <joint_properties damping="0.0" friction="0.0"/>
  </joint>
  <!-- LINK: upper_leg_${location}_link -->
  <link name="upper_leg_back_leftR_link">
    <visual>
      <geometry>
        <box size="0.039 0.008 0.1"/>
      </geometry>
    </visual>
    <collision>
      <geometry>
        <box size="0.039 0.008 0.1"/>
      </geometry>
    </collision>
    <inertial>
      <mass value="0.05"/>
      <inertia ixx=".000038770" ixy=".0" ixz=".0" iyy=".000042198" iyz=".0" izz=".0000036030"/>
    </inertial>
  </link>
  <gazebo reference="upper_leg_back_leftR_link">
    <material>Gazebo/Grey</material>
  </gazebo>
  <!-- JOINT: ${hip}_${location}_link to motor_${location}_link -->
  <joint name="hip_back_leftR_link" type="fixed">
    <axis xyz="0 0 1"/>
    <parent link="motor_back_leftR_link"/>
    <child link="upper_leg_back_leftR_link"/>
    <origin rpy="-1.57075 0 0" xyz="0 .045 -.0145"/>
    <limit effort="100" velocity="100"/>
    <joint_properties damping="0.0" friction="0.0"/>
  </joint>
  <!-- LINK: upper_leg_${location}_link -->
  <link name="upper_leg_back_leftL_link">
    <visual>
      <geometry>
        <box size="0.039 0.008 0.1"/>
      </geometry>
    </visual>
    <collision>
      <geometry>
        <box size="0.039 0.008 0.1"/>
      </geometry>
    </collision>
    <inertial>
      <mass value="0.05"/>
      <inertia ixx=".000038770" ixy=".0" ixz=".0" iyy=".000042198" iyz=".0" izz=".0000036030"/>
    </inertial>
  </link>
  <gazebo reference="upper_leg_back_leftL_link">
    <material>Gazebo/Grey</material>
  </gazebo>
  <!-- JOINT: ${hip}_${location}_link to motor_${location}_link -->
  <joint name="motor_back_leftL_link" type="fixed">
    <axis xyz="0 0 1"/>
    <parent link="motor_back_leftL_link"/>
    <child link="upper_leg_back_leftL_link"/>
    <origin rpy="-1.57075 0 0" xyz="0 .045 .0145"/>
    <limit effort="100" velocity="100"/>
    <joint_properties damping="0.0" friction="0.0"/>
  </joint>
  <!-- Lower legs and flexy knee joints -->
  <!-- LINK: lower_leg_${location}_link -->
  <link name="lower_leg_front_leftL_link">
    <visual>
      <origin rpy="0 0 0" xyz="0 0 0.11"/>
      <geometry>
        <box size="0.017 0.009 0.22"/>
      </geometry>
    </visual>
    <collision>
      <origin rpy="0 0 0" xyz="0 0 0.11"/>
      <geometry>
        <box size="0.017 0.009 0.22"/>
      </geometry>
    </collision>
    <inertial>
      <origin rpy="0 0 0" xyz="0 0 0.11"/>
      <mass value="0.05"/>
      <inertia ixx=".00032459" ixy=".0" ixz=".0" iyy=".00032637" iyz=".0" izz=".000002178"/>
    </inertial>
  </link>
  <gazebo reference="lower_leg_front_leftL_link">
    <material>Gazebo/Grey</material>
    <collision>
      <surface>
        <bounce>
          <restitution_coefficient>0</restitution_coefficient>
          <threshold>1e+06</threshold>
        </bounce>
        <friction>
          <torsional>
            <coefficient>0.05</coefficient>
          </torsional>
          <bullet>
            <rolling_friction>0.05</rolling_friction>
          </bullet>
        </friction>
        <contact>
          <ode>
            <kp>3000.0</kp>
            <kd>100.0</kd>
          </ode>
          <bullet>
            <kp>3000.0</kp>
            <kd>100.0</kd>
          </bullet>
        </contact>
      </surface>
    </collision>
  </gazebo>
  <!-- JOINT: lower_leg_${location}_link to upper_leg_${location}_link -->
  <joint name="8" type="continuous">
    <axis xyz="0 -1 0"/>
    <parent link="upper_leg_front_leftL_link"/>
    <child link="lower_leg_front_leftL_link"/>
    <origin rpy="0 4.189 0" xyz="0 -0.0085 0.05"/>
    <limit effort="100" velocity="100"/>
    <joint_properties damping="0.0" friction="0.0"/>
  </joint>
  <!-- Toe -->
  <!-- LINK: toe${toeSuffix} -->
  <link name="toe0">
    <visual>
      <origin rpy="0 0 0" xyz="0 0 0"/>
      <geometry>
        <sphere radius="0.015"/>
      </geometry>
    </visual>
    <collision>
      <origin rpy="0 0 0" xyz="0 0 0"/>
      <geometry>
        <sphere radius="0.015"/>
      </geometry>
    </collision>
    <inertial>
      <mass value="0.01"/>
      <inertia ixx="0.000025" ixy="0" ixz="0" iyy="0.000025" iyz="0" izz="0.000025"/>
    </inertial>
  </link>
  <gazebo reference="toe0">
    <material>Gazebo/Black</material>
    <collision>
      <surface>
        <bounce>
          <restitution_coefficient>0</restitution_coefficient>
          <threshold>1e+06</threshold>
        </bounce>
        <friction>
          <torsional>
            <coefficient>1.0</coefficient>
          </torsional>
          <ode>
            <mu>1.0</mu>
            <mu2>1.0</mu2>
          </ode>
          <bullet>
            <rolling_friction>1.0</rolling_friction>
            <friction2>1.0</friction2>
          </bullet>
        </friction>
        <contact>
          <ode>
            <kp>300000.0</kp>
            <kd>1000.0</kd>
          </ode>
          <bullet>
            <kp>300000.0</kp>
            <kd>1000.0</kd>
          </bullet>
        </contact>
      </surface>
    </collision>
  </gazebo>
  <!-- JOINT: toe${toeSuffix} to lower_leg_${location}_link -->
  <joint name="toe0" type="fixed">
    <parent link="lower_leg_front_leftL_link"/>
    <child link="toe0"/>
    <origin xyz="0 0 0.22"/>
    <dynamics damping="0.0" friction="0.0"/>
  </joint>
  <!-- LINK: lower_leg_${location}_link -->
  <link name="lower_leg_front_leftR_link">
    <visual>
      <origin rpy="0 0 0" xyz="0 0 0.1"/>
      <geometry>
        <box size="0.017 0.009 0.2"/>
      </geometry>
    </visual>
    <collision>
      <origin rpy="0 0 0" xyz="0 0 0.1"/>
      <geometry>
        <box size="0.017 0.009 0.2"/>
      </geometry>
    </collision>
    <inertial>
      <origin rpy="0 0 0" xyz="0 0 0.1"/>
      <mass value="0.05"/>
      <inertia ixx=".00032459" ixy=".0" ixz=".0" iyy=".00032637" iyz=".0" izz=".000002178"/>
    </inertial>
  </link>
  <gazebo reference="lower_leg_front_leftR_link">
    <material>Gazebo/Grey</material>
    <collision>
      <surface>
        <bounce>
          <restitution_coefficient>0</restitution_coefficient>
          <threshold>1e+06</threshold>
        </bounce>
        <friction>
          <torsional>
            <coefficient>0.05</coefficient>
          </torsional>
          <bullet>
            <rolling_friction>0.05</rolling_friction>
          </bullet>
        </friction>
        <contact>
          <ode>
            <kp>3000.0</kp>
            <kd>100.0</kd>
          </ode>
          <bullet>
            <kp>3000.0</kp>
            <kd>100.0</kd>
          </bullet>
        </contact>
      </surface>
    </collision>
  </gazebo>
  <!-- JOINT: lower_leg_${location}_link to upper_leg_${location}_link -->
  <joint name="9" type="continuous">
    <axis xyz="0 1 0"/>
    <parent link="upper_leg_front_leftR_link"/>
    <child link="lower_leg_front_leftR_link"/>
    <origin rpy="0 -4.189 0" xyz="0 0.0085 0.05"/>
    <limit effort="100" velocity="100"/>
    <joint_properties damping="0.0" friction="0.0"/>
  </joint>
  <!-- LINK: lower_leg_${location}_link -->
  <link name="lower_leg_back_leftL_link">
    <visual>
      <origin rpy="0 0 0" xyz="0 0 0.11"/>
      <geometry>
        <box size="0.017 0.009 0.22"/>
      </geometry>
    </visual>
    <collision>
      <origin rpy="0 0 0" xyz="0 0 0.11"/>
      <geometry>
        <box size="0.017 0.009 0.22"/>
      </geometry>
    </collision>
    <inertial>
      <origin rpy="0 0 0" xyz="0 0 0.11"/>
      <mass value="0.05"/>
      <inertia ixx=".00032459" ixy=".0" ixz=".0" iyy=".00032637" iyz=".0" izz=".000002178"/>
    </inertial>
  </link>
  <gazebo reference="lower_leg_back_leftL_link">
    <material>Gazebo/Grey</material>
    <collision>
      <surface>
        <bounce>
          <restitution_coefficient>0</restitution_coefficient>
          <threshold>1e+06</threshold>
        </bounce>
        <friction>
          <torsional>
            <coefficient>0.05</coefficient>
          </torsional>
          <bullet>
            <rolling_friction>0.05</rolling_friction>
          </bullet>
        </friction>
        <contact>
          <ode>
            <kp>3000.0</kp>
            <kd>100.0</kd>
          </ode>
          <bullet>
            <kp>3000.0</kp>
            <kd>100.0</kd>
          </bullet>
        </contact>
      </surface>
    </collision>
  </gazebo>
  <!-- JOINT: lower_leg_${location}_link to upper_leg_${location}_link -->
  <joint name="10" type="continuous">
    <axis xyz="0 -1 0"/>
    <parent link="upper_leg_back_leftL_link"/>
    <child link="lower_leg_back_leftL_link"/>
    <origin rpy="0 4.189 0" xyz="0 -0.0085 0.05"/>
    <limit effort="100" velocity="100"/>
    <joint_properties damping="0.0" friction="0.0"/>
  </joint>
  <!-- Toe -->
  <!-- LINK: toe${toeSuffix} -->
  <link name="toe2">
    <visual>
      <origin rpy="0 0 0" xyz="0 0 0"/>
      <geometry>
        <sphere radius="0.015"/>
      </geometry>
    </visual>
    <collision>
      <origin rpy="0 0 0" xyz="0 0 0"/>
      <geometry>
        <sphere radius="0.015"/>
      </geometry>
    </collision>
    <inertial>
      <mass value="0.01"/>
      <inertia ixx="0.000025" ixy="0" ixz="0" iyy="0.000025" iyz="0" izz="0.000025"/>
    </inertial>
  </link>
  <gazebo reference="toe2">
    <material>Gazebo/Black</material>
    <collision>
      <surface>
        <bounce>
          <restitution_coefficient>0</restitution_coefficient>
          <threshold>1e+06</threshold>
        </bounce>
        <friction>
          <torsional>
            <coefficient>1.0</coefficient>
          </torsional>
          <ode>
            <mu>1.0</mu>
            <mu2>1.0</mu2>
          </ode>
          <bullet>
            <rolling_friction>1.0</rolling_friction>
            <friction2>1.0</friction2>
          </bullet>
        </friction>
        <contact>
          <ode>
            <kp>300000.0</kp>
            <kd>1000.0</kd>
          </ode>
          <bullet>
            <kp>300000.0</kp>
            <kd>1000.0</kd>
          </bullet>
        </contact>
      </surface>
    </collision>
  </gazebo>
  <!-- JOINT: toe${toeSuffix} to lower_leg_${location}_link -->
  <joint name="toe2" type="fixed">
    <parent link="lower_leg_back_leftL_link"/>
    <child link="toe2"/>
    <origin xyz="0 0 0.22"/>
    <dynamics damping="0.0" friction="0.0"/>
  </joint>
  <!-- LINK: lower_leg_${location}_link -->
  <link name="lower_leg_back_leftR_link">
    <visual>
      <origin rpy="0 0 0" xyz="0 0 0.1"/>
      <geometry>
        <box size="0.017 0.009 0.2"/>
      </geometry>
    </visual>
    <collision>
      <origin rpy="0 0 0" xyz="0 0 0.1"/>
      <geometry>
        <box size="0.017 0.009 0.2"/>
      </geometry>
    </collision>
    <inertial>
      <origin rpy="0 0 0" xyz="0 0 0.1"/>
      <mass value="0.05"/>
      <inertia ixx=".00032459" ixy=".0" ixz=".0" iyy=".00032637" iyz=".0" izz=".000002178"/>
    </inertial>
  </link>
  <gazebo reference="lower_leg_back_leftR_link">
    <material>Gazebo/Grey</material>
    <collision>
      <surface>
        <bounce>
          <restitution_coefficient>0</restitution_coefficient>
          <threshold>1e+06</threshold>
        </bounce>
        <friction>
          <torsional>
            <coefficient>0.05</coefficient>
          </torsional>
          <bullet>
            <rolling_friction>0.05</rolling_friction>
          </bullet>
        </friction>
        <contact>
          <ode>
            <kp>3000.0</kp>
            <kd>100.0</kd>
          </ode>
          <bullet>
            <kp>3000.0</kp>
            <kd>100.0</kd>
          </bullet>
        </contact>
      </surface>
    </collision>
  </gazebo>
  <!-- JOINT: lower_leg_${location}_link to upper_leg_${location}_link -->
  <joint name="11" type="continuous">
    <axis xyz="0 1 0"/>
    <parent link="upper_leg_back_leftR_link"/>
    <child link="lower_leg_back_leftR_link"/>
    <origin rpy="0 -4.189 0" xyz="0 0.0085 0.05"/>
    <limit effort="100" velocity="100"/>
    <joint_properties damping="0.0" friction="0.0"/>
  </joint>
  <!-- LINK: lower_leg_${location}_link -->
  <link name="lower_leg_front_rightL_link">
    <visual>
      <origin rpy="0 0 0" xyz="0 0 0.1"/>
      <geometry>
        <box size="0.017 0.009 0.2"/>
      </geometry>
    </visual>
    <collision>
      <origin rpy="0 0 0" xyz="0 0 0.1"/>
      <geometry>
        <box size="0.017 0.009 0.2"/>
      </geometry>
    </collision>
    <inertial>
      <origin rpy="0 0 0" xyz="0 0 0.1"/>
      <mass value="0.05"/>
      <inertia ixx=".00032459" ixy=".0" ixz=".0" iyy=".00032637" iyz=".0" izz=".000002178"/>
    </inertial>
  </link>
  <gazebo reference="lower_leg_front_rightL_link">
    <material>Gazebo/Grey</material>
    <collision>
      <surface>
        <bounce>
          <restitution_coefficient>0</restitution_coefficient>
          <threshold>1e+06</threshold>
        </bounce>
        <friction>
          <torsional>
            <coefficient>0.05</coefficient>
          </torsional>
          <bullet>
            <rolling_friction>0.05</rolling_friction>
          </bullet>
        </friction>
        <contact>
          <ode>
            <kp>3000.0</kp>
            <kd>100.0</kd>
          </ode>
          <bullet>
            <kp>3000.0</kp>
            <kd>100.0</kd>
          </bullet>
        </contact>
      </surface>
    </collision>
  </gazebo>
  <!-- JOINT: lower_leg_${location}_link to upper_leg_${location}_link -->
  <joint name="12" type="continuous">
    <axis xyz="0 -1 0"/>
    <parent link="upper_leg_front_rightL_link"/>
    <child link="lower_leg_front_rightL_link"/>
    <origin rpy="0 -4.189 0" xyz="0 -0.0085 0.05"/>
    <limit effort="100" velocity="100"/>
    <joint_properties damping="0.0" friction="0.0"/>
  </joint>
  <!-- LINK: lower_leg_${location}_link -->
  <link name="lower_leg_front_rightR_link">
    <visual>
      <origin rpy="0 0 0" xyz="0 0 0.11"/>
      <geometry>
        <box size="0.017 0.009 0.22"/>
      </geometry>
    </visual>
    <collision>
      <origin rpy="0 0 0" xyz="0 0 0.11"/>
      <geometry>
        <box size="0.017 0.009 0.22"/>
      </geometry>
    </collision>
    <inertial>
      <origin rpy="0 0 0" xyz="0 0 0.11"/>
      <mass value="0.05"/>
      <inertia ixx=".00032459" ixy=".0" ixz=".0" iyy=".00032637" iyz=".0" izz=".000002178"/>
    </inertial>
  </link>
  <gazebo reference="lower_leg_front_rightR_link">
    <material>Gazebo/Grey</material>
    <collision>
      <surface>
        <bounce>
          <restitution_coefficient>0</restitution_coefficient>
          <threshold>1e+06</threshold>
        </bounce>
        <friction>
          <torsional>
            <coefficient>0.05</coefficient>
          </torsional>
          <bullet>
            <rolling_friction>0.05</rolling_friction>
          </bullet>
        </friction>
        <contact>
          <ode>
            <kp>3000.0</kp>
            <kd>100.0</kd>
          </ode>
          <bullet>
            <kp>3000.0</kp>
            <kd>100.0</kd>
          </bullet>
        </contact>
      </surface>
    </collision>
  </gazebo>
  <!-- JOINT: lower_leg_${location}_link to upper_leg_${location}_link -->
  <joint name="13" type="continuous">
    <axis xyz="0 1 0"/>
    <parent link="upper_leg_front_rightR_link"/>
    <child link="lower_leg_front_rightR_link"/>
    <origin rpy="0 4.189 0" xyz="0 0.0085 0.05"/>
    <limit effort="100" velocity="100"/>
    <joint_properties damping="0.0" friction="0.0"/>
  </joint>
  <!-- Toe -->
  <!-- LINK: toe${toeSuffix} -->
  <link name="toe5">
    <visual>
      <origin rpy="0 0 0" xyz="0 0 0"/>
      <geometry>
        <sphere radius="0.015"/>
      </geometry>
    </visual>
    <collision>
      <origin rpy="0 0 0" xyz="0 0 0"/>
      <geometry>
        <sphere radius="0.015"/>
      </geometry>
    </collision>
    <inertial>
      <mass value="0.01"/>
      <inertia ixx="0.000025" ixy="0" ixz="0" iyy="0.000025" iyz="0" izz="0.000025"/>
    </inertial>
  </link>
  <gazebo reference="toe5">
    <material>Gazebo/Black</material>
    <collision>
      <surface>
        <bounce>
          <restitution_coefficient>0</restitution_coefficient>
          <threshold>1e+06</threshold>
        </bounce>
        <friction>
          <torsional>
            <coefficient>1.0</coefficient>
          </torsional>
          <ode>
            <mu>1.0</mu>
            <mu2>1.0</mu2>
          </ode>
          <bullet>
            <rolling_friction>1.0</rolling_friction>
            <friction2>1.0</friction2>
          </bullet>
        </friction>
        <contact>
          <ode>
            <kp>300000.0</kp>
            <kd>1000.0</kd>
          </ode>
          <bullet>
            <kp>300000.0</kp>
            <kd>1000.0</kd>
          </bullet>
        </contact>
      </surface>
    </collision>
  </gazebo>
  <!-- JOINT: toe${toeSuffix} to lower_leg_${location}_link -->
  <joint name="toe5" type="fixed">
    <parent link="lower_leg_front_rightR_link"/>
    <child link="toe5"/>
    <origin xyz="0 0 0.22"/>
    <dynamics damping="0.0" friction="0.0"/>
  </joint>
  <!-- LINK: lower_leg_${location}_link -->
  <link name="lower_leg_back_rightL_link">
    <visual>
      <origin rpy="0 0 0" xyz="0 0 0.1"/>
      <geometry>
        <box size="0.017 0.009 0.2"/>
      </geometry>
    </visual>
    <collision>
      <origin rpy="0 0 0" xyz="0 0 0.1"/>
      <geometry>
        <box size="0.017 0.009 0.2"/>
      </geometry>
    </collision>
    <inertial>
      <origin rpy="0 0 0" xyz="0 0 0.1"/>
      <mass value="0.05"/>
      <inertia ixx=".00032459" ixy=".0" ixz=".0" iyy=".00032637" iyz=".0" izz=".000002178"/>
    </inertial>
  </link>
  <gazebo reference="lower_leg_back_rightL_link">
    <material>Gazebo/Grey</material>
    <collision>
      <surface>
        <bounce>
          <restitution_coefficient>0</restitution_coefficient>
          <threshold>1e+06</threshold>
        </bounce>
        <friction>
          <torsional>
            <coefficient>0.05</coefficient>
          </torsional>
          <bullet>
            <rolling_friction>0.05</rolling_friction>
          </bullet>
        </friction>
        <contact>
          <ode>
            <kp>3000.0</kp>
            <kd>100.0</kd>
          </ode>
          <bullet>
            <kp>3000.0</kp>
            <kd>100.0</kd>
          </bullet>
        </contact>
      </surface>
    </collision>
  </gazebo>
  <!-- JOINT: lower_leg_${location}_link to upper_leg_${location}_link -->
  <joint name="14" type="continuous">
    <axis xyz="0 -1 0"/>
    <parent link="upper_leg_back_rightL_link"/>
    <child link="lower_leg_back_rightL_link"/>
    <origin rpy="0 -4.189 0" xyz="0 -0.0085 0.05"/>
    <limit effort="100" velocity="100"/>
    <joint_properties damping="0.0" friction="0.0"/>
  </joint>
  <!-- LINK: lower_leg_${location}_link -->
  <link name="lower_leg_back_rightR_link">
    <visual>
      <origin rpy="0 0 0" xyz="0 0 0.11"/>
      <geometry>
        <box size="0.017 0.009 0.22"/>
      </geometry>
    </visual>
    <collision>
      <origin rpy="0 0 0" xyz="0 0 0.11"/>
      <geometry>
        <box size="0.017 0.009 0.22"/>
      </geometry>
    </collision>
    <inertial>
      <origin rpy="0 0 0" xyz="0 0 0.11"/>
      <mass value="0.05"/>
      <inertia ixx=".00032459" ixy=".0" ixz=".0" iyy=".00032637" iyz=".0" izz=".000002178"/>
    </inertial>
  </link>
  <gazebo reference="lower_leg_back_rightR_link">
    <material>Gazebo/Grey</material>
    <collision>
      <surface>
        <bounce>
          <restitution_coefficient>0</restitution_coefficient>
          <threshold>1e+06</threshold>
        </bounce>
        <friction>
          <torsional>
            <coefficient>0.05</coefficient>
          </torsional>
          <bullet>
            <rolling_friction>0.05</rolling_friction>
          </bullet>
        </friction>
        <contact>
          <ode>
            <kp>3000.0</kp>
            <kd>100.0</kd>
          </ode>
          <bullet>
            <kp>3000.0</kp>
            <kd>100.0</kd>
          </bullet>
        </contact>
      </surface>
    </collision>
  </gazebo>
  <!-- JOINT: lower_leg_${location}_link to upper_leg_${location}_link -->
  <joint name="15" type="continuous">
    <axis xyz="0 1 0"/>
    <parent link="upper_leg_back_rightR_link"/>
    <child link="lower_leg_back_rightR_link"/>
    <origin rpy="0 4.189 0" xyz="0 0.0085 0.05"/>
    <limit effort="100" velocity="100"/>
    <joint_properties damping="0.0" friction="0.0"/>
  </joint>
  <!-- Toe -->
  <!-- LINK: toe${toeSuffix} -->
  <link name="toe7">
    <visual>
      <origin rpy="0 0 0" xyz="0 0 0"/>
      <geometry>
        <sphere radius="0.015"/>
      </geometry>
    </visual>
    <collision>
      <origin rpy="0 0 0" xyz="0 0 0"/>
      <geometry>
        <sphere radius="0.015"/>
      </geometry>
    </collision>
    <inertial>
      <mass value="0.01"/>
      <inertia ixx="0.000025" ixy="0" ixz="0" iyy="0.000025" iyz="0" izz="0.000025"/>
    </inertial>
  </link>
  <gazebo reference="toe7">
    <material>Gazebo/Black</material>
    <collision>
      <surface>
        <bounce>
          <restitution_coefficient>0</restitution_coefficient>
          <threshold>1e+06</threshold>
        </bounce>
        <friction>
          <torsional>
            <coefficient>1.0</coefficient>
          </torsional>
          <ode>
            <mu>1.0</mu>
            <mu2>1.0</mu2>
          </ode>
          <bullet>
            <rolling_friction>1.0</rolling_friction>
            <friction2>1.0</friction2>
          </bullet>
        </friction>
        <contact>
          <ode>
            <kp>300000.0</kp>
            <kd>1000.0</kd>
          </ode>
          <bullet>
            <kp>300000.0</kp>
            <kd>1000.0</kd>
          </bullet>
        </contact>
      </surface>
    </collision>
  </gazebo>
  <!-- JOINT: toe${toeSuffix} to lower_leg_${location}_link -->
  <joint name="toe7" type="fixed">
    <parent link="lower_leg_back_rightR_link"/>
    <child link="toe7"/>
    <origin xyz="0 0 0.22"/>
    <dynamics damping="0.0" friction="0.0"/>
  </joint>
  <!-- Add ros_control plugin -->
  <gazebo>
    <plugin filename="libgazebo_ros_control.so" name="gazebo_ros_control">
      <robotNamespace>/minitaur</robotNamespace>
    </plugin>
  </gazebo>
</robot>

