<?xml version="1.0" encoding="utf-8"?>
<!-- =================================================================================== -->
<!-- |    This document was autogenerated by xacro from CartPole.urdf.xacro            | -->
<!-- |    EDITING THIS FILE BY HAND IS NOT RECOMMENDED                                 | -->
<!-- =================================================================================== -->
<robot name="cartpole_xacro" xmlns:xacro="http://www.ros.org/wiki/xacro">
  <!-- ====== -->
  <!-- COLORS -->
  <!-- ====== -->
  <material name="black">
    <color rgba="0 0 0 0.8"/>
  </material>
  <material name="white">
    <color rgba="1 1 1 0.8"/>
  </material>
  <material name="grey">
    <color rgba="0.2 0.2 0.2 0.8"/>
  </material>
  <gazebo reference="rail">
    <visual>
      <material>
        <ambient>0 0 0 0.8</ambient>
        <diffuse>0 0 0 0.8</diffuse>
        <specular>0 0 0 0.8</specular>
        <emissive>0 0 0 0.8</emissive>
        <script>
          <uri/>
          <name/>
        </script>
      </material>
    </visual>
  </gazebo>
  <gazebo reference="cart">
    <visual>
      <material>
        <ambient>0.2 0.2 0.2 0.8</ambient>
        <diffuse>0.2 0.2 0.2 0.8</diffuse>
        <specular>0.2 0.2 0.2 0.8</specular>
        <emissive>0.2 0.2 0.2 0.8</emissive>
        <script>
          <uri/>
          <name/>
        </script>
      </material>
    </visual>
  </gazebo>
  <gazebo reference="pole">
    <visual>
      <material>
        <ambient>1 0 0 0.8</ambient>
        <diffuse>1 0 0 0.8</diffuse>
        <specular>1 0 0 0.8</specular>
        <emissive>1 0 0 0.8</emissive>
        <script>
          <uri/>
          <name/>
        </script>
      </material>
    </visual>
  </gazebo>
  <!-- ===== -->
  <!-- LINKS -->
  <!-- ===== -->
  <link name="world"/>
  <link name="rail">
    <inertial>
      <!-- This link is fixed, inertial values are not relevant -->
      <origin rpy="0 0 0" xyz="0 0 0"/>
      <mass value="5"/>
      <inertia ixx="100" ixy="0" ixz="0" iyy="100" iyz="0" izz="100"/>
    </inertial>
    <visual>
      <geometry>
        <cylinder length="5" radius="0.005"/>
      </geometry>
      <origin rpy="1.57079632679 0 0" xyz="0 0 0"/>
      <material name="black">
        <color rgba="0 0 0 0.8"/>
      </material>
    </visual>
  </link>
  <link name="cart">
    <inertial>
      <origin rpy="0 0 0" xyz="0 0 0"/>
      <mass value="1.0"/>
      <inertia ixx="0.00354166666667" ixy="0" ixz="0" iyy="0.00416666666667" iyz="0" izz="0.00104166666667"/>
    </inertial>
    <visual>
      <geometry>
        <box size="0.1 0.2 0.05"/>
      </geometry>
      <origin rpy="0 0 0" xyz="0 0 0"/>
      <material name="grey">
        <color rgba="0.2 0.2 0.2 0.8"/>
      </material>
    </visual>
  </link>
  <link name="pole">
    <inertial>
      <origin rpy="0 0 0" xyz="0 0 0.5"/>
      <mass value="0.1"/>
      <inertia ixx="1e-09" ixy="0" ixz="0" iyy="0.0333333333333" iyz="0" izz="0.0333333333333"/>
    </inertial>
    <visual>
      <geometry>
        <cylinder length="1.0" radius="0.005"/>
      </geometry>
      <origin rpy="0 0 0" xyz="0 0 0.5"/>
      <material name="red">
        <color rgba="1 0 0 0.8"/>
      </material>
    </visual>
  </link>
  <!-- ====== -->
  <!-- JOINTS -->
  <!-- ====== -->
  <!--  http://gazebosim.org/tutorials/?tut=ros_urdf#RigidlyFixingAModeltotheWorld-->
  <joint name="world_to_rail" type="fixed">
    <parent link="world"/>
    <child link="rail"/>
    <origin rpy="0 0 0" xyz="0 0 0.5"/>
  </joint>
  <joint name="linear" type="prismatic">
    <parent link="rail"/>
    <child link="cart"/>
    <axis xyz="0 1 0"/>
    <origin rpy="0 0 0" xyz="0 0 0"/>
    <limit effort="500" lower="-2.4" upper="2.4" velocity="10"/>
  </joint>
  <joint name="pivot" type="continuous">
    <parent link="cart"/>
    <child link="pole"/>
    <axis xyz="1 0 0"/>
    <origin rpy="0 0 0" xyz="0 0 0.025"/>
    <limit effort="500" lower="-1.57079632679" upper="1.57079632679" velocity="10"/>
  </joint>
</robot>

