<sdf version='1.6'>
  <model name='cartpole_xacro'>
    <link name='rail'>
      <pose frame=''>0 0 0.5 0 -0 0</pose>
      <inertial>
        <pose frame=''>0 0 0 0 -0 0</pose>
        <mass>5</mass>
        <inertia>
          <ixx>100</ixx>
          <ixy>0</ixy>
          <ixz>0</ixz>
          <iyy>100</iyy>
          <iyz>0</iyz>
          <izz>100</izz>
        </inertia>
      </inertial>
      <visual name='rail_visual'>
        <pose frame=''>0 0 0 1.5708 -0 0</pose>
        <geometry>
          <cylinder>
            <length>5</length>
            <radius>0.005</radius>
          </cylinder>
        </geometry>
        <material>
          <ambient>0 0 0 0.8</ambient>
          <diffuse>0 0 0 0.8</diffuse>
          <specular>0 0 0 0.8</specular>
          <emissive>0 0 0 0.8</emissive>
          <!--<script>
            <uri>__default__</uri>
            <name>__default__</name>
          </script>-->
        </material>
      </visual>
      <gravity>1</gravity>
      <velocity_decay/>
    </link>
    <joint name='world_to_rail' type='fixed'>
      <child>rail</child>
      <parent>world</parent>
    </joint>
    <link name='cart'>
      <pose frame=''>0 0 0.5 0 -0 0</pose>
      <inertial>
        <pose frame=''>0 0 0 0 -0 0</pose>
        <mass>1</mass>
        <inertia>
          <ixx>0.00354167</ixx>
          <ixy>0</ixy>
          <ixz>0</ixz>
          <iyy>0.00416667</iyy>
          <iyz>0</iyz>
          <izz>0.00104167</izz>
        </inertia>
      </inertial>
      <visual name='cart_visual'>
        <pose frame=''>0 0 0 0 -0 0</pose>
        <geometry>
          <box>
            <size>0.1 0.2 0.05</size>
          </box>
        </geometry>
        <material>
          <ambient>0.2 0.2 0.2 0.8</ambient>
          <diffuse>0.2 0.2 0.2 0.8</diffuse>
          <specular>0.2 0.2 0.2 0.8</specular>
          <emissive>0.2 0.2 0.2 0.8</emissive>
          <!--<script>
            <uri>__default__</uri>
            <name>__default__</name>
          </script>-->
        </material>
      </visual>
      <gravity>1</gravity>
      <velocity_decay/>
    </link>
    <joint name='linear' type='prismatic'>
      <child>cart</child>
      <parent>rail</parent>
      <axis>
        <xyz>0 1 0</xyz>
        <limit>
          <lower>-2.4</lower>
          <upper>2.4</upper>
          <effort>500</effort>
          <velocity>10</velocity>
        </limit>
        <dynamics>
          <spring_reference>0</spring_reference>
          <spring_stiffness>0</spring_stiffness>
        </dynamics>
        <use_parent_model_frame>1</use_parent_model_frame>
      </axis>
    </joint>
    <link name='pole'>
      <pose frame=''>0 0 0.525 0 -0 0</pose>
      <inertial>
        <pose frame=''>0 0 0.5 0 -0 0</pose>
        <mass>0.1</mass>
        <inertia>
          <ixx>1e-09</ixx>
          <ixy>0</ixy>
          <ixz>0</ixz>
          <iyy>0.0333333</iyy>
          <iyz>0</iyz>
          <izz>0.0333333</izz>
        </inertia>
      </inertial>
      <visual name='pole_visual'>
        <pose frame=''>0 0 0.5 0 -0 0</pose>
        <geometry>
          <cylinder>
            <length>1</length>
            <radius>0.005</radius>
          </cylinder>
        </geometry>
        <material>
          <ambient>1 0 0 0.8</ambient>
          <diffuse>1 0 0 0.8</diffuse>
          <specular>1 0 0 0.8</specular>
          <emissive>1 0 0 0.8</emissive>
          <!--<script>
            <uri>__default__</uri>
            <name>__default__</name>
          </script>-->
        </material>
      </visual>
      <gravity>1</gravity>
      <velocity_decay/>
    </link>
    <joint name='pivot' type='revolute'>
      <child>pole</child>
      <parent>cart</parent>
      <axis>
        <xyz>1 0 0</xyz>
        <limit>
          <lower>-1e+16</lower>
          <upper>1e+16</upper>
        </limit>
        <dynamics>
          <spring_reference>0</spring_reference>
          <spring_stiffness>0</spring_stiffness>
        </dynamics>
        <use_parent_model_frame>1</use_parent_model_frame>
      </axis>
    </joint>
  </model>
</sdf>
