<?xml version="1.0" encoding="utf-8"?>
<sdf version='1.6'>
  <model name='iCub'>
    <link name='base_link'>
      <pose>0 0 0 0 -0 0</pose>
      <inertial>
        <pose>0.024882 0.000104 -0.044081 0 -0 0</pose>
        <mass>5.09143</mass>
        <inertia>
          <ixx>0.0249124</ixx>
          <ixy>-1.55458e-05</ixy>
          <ixz>0.00170968</ixz>
          <iyy>0.0139679</iyy>
          <iyz>5.93488e-06</iyz>
          <izz>0.0202112</izz>
        </inertia>
      </inertial>
      <collision name='base_link_fixed_joint_lump__root_link_collision'>
        <pose>-0.0364 0 0.032 1.5708 0 -1.5708</pose>
        <geometry>
          <mesh>
            <scale>0.001 0.001 0.001</scale>
            <uri>file://iCub/meshes/simmechanics/sim_sea_2-5_root_link_prt-binary.stl</uri>
          </mesh>
        </geometry>
        <surface>
          <contact>
            <ode/>
          </contact>
          <friction>
            <ode/>
          </friction>
        </surface>
      </collision>
      <visual name='base_link_fixed_joint_lump__root_link_visual'>
        <pose>-0.0364 0 0.032 1.5708 0 -1.5708</pose>
        <geometry>
          <mesh>
            <scale>0.001 0.001 0.001</scale>
            <uri>file://iCub/meshes/simmechanics/sim_sea_2-5_root_link_prt-binary.stl</uri>
          </mesh>
        </geometry>
        <material>
          <diffuse>1 1 1 1</diffuse>
        </material>
      </visual>
      <velocity_decay/>
    </link>
    <link name='l_hip_1'>
      <pose>0.006452 -0.026 -0.119913 0 -0 3.14159</pose>
      <inertial>
        <pose>-0.000511 0.038092 -8.3e-05 1.5708 -0 1.5708</pose>
        <mass>0.919725</mass>
        <inertia>
          <ixx>0.000404539</ixx>
          <ixy>1.18502e-06</ixy>
          <ixz>-9.64514e-07</ixz>
          <iyy>0.000573315</iyy>
          <iyz>-1.06028e-06</iyz>
          <izz>0.000578982</izz>
        </inertia>
      </inertial>
      <collision name='l_hip_1_collision'>
        <pose>0.042852 -0.026 0.151913 1.5708 -0 1.5708</pose>
        <geometry>
          <mesh>
            <scale>0.001 0.001 0.001</scale>
            <uri>file://iCub/meshes/simmechanics/sim_sea_2-5_l_hip_1_prt-binary.stl</uri>
          </mesh>
        </geometry>
      </collision>
      <visual name='l_hip_1_visual'>
        <pose>0.042852 -0.026 0.151913 1.5708 -0 1.5708</pose>
        <geometry>
          <mesh>
            <scale>0.001 0.001 0.001</scale>
            <uri>file://iCub/meshes/simmechanics/sim_sea_2-5_l_hip_1_prt-binary.stl</uri>
          </mesh>
        </geometry>
        <material>
          <diffuse>1 1 1 1</diffuse>
        </material>
      </visual>
    </link>
    <joint name='l_hip_pitch' type='revolute'>
      <child>l_hip_1</child>
      <parent>base_link</parent>
      <axis>
        <xyz>-0 -1 0</xyz>
        <limit>
          <lower>-0.785398</lower>
          <upper>2.33874</upper>
          <effort>55.5</effort>
          <velocity>5.1</velocity>
        </limit>
        <dynamics>
          <damping>1</damping>
          <friction>0</friction>
          <spring_reference>0</spring_reference>
          <spring_stiffness>0</spring_stiffness>
        </dynamics>
        <use_parent_model_frame>0</use_parent_model_frame>
      </axis>
      <physics>
        <ode>
          <implicit_spring_damper>1</implicit_spring_damper>
          <cfm_damping>1</cfm_damping>
          <limit>
            <cfm>0</cfm>
            <erp>0.2</erp>
          </limit>
        </ode>
      </physics>
    </joint>
    <link name='l_hip_2'>
      <pose>0.006452 -0.0701 -0.119913 0 -0 3.14159</pose>
      <inertial>
        <pose>-0.001576 -1.9e-05 -0.044053 1.5708 -0 1.5708</pose>
        <mass>0.421106</mass>
        <inertia>
          <ixx>0.000494284</ixx>
          <ixy>1.5483e-07</ixy>
          <ixz>-1.86308e-07</ixz>
          <iyy>0.000288736</iyy>
          <iyz>1.52962e-05</iyz>
          <izz>0.000319008</izz>
        </inertia>
      </inertial>
      <collision name='l_hip_2_collision'>
        <pose>0.042852 -0.0701 0.151913 1.5708 -0 1.5708</pose>
        <geometry>
          <mesh>
            <scale>0.001 0.001 0.001</scale>
            <uri>file://iCub/meshes/simmechanics/sim_sea_2-5_l_hip_2_prt-binary.stl</uri>
          </mesh>
        </geometry>
      </collision>
      <visual name='l_hip_2_visual'>
        <pose>0.042852 -0.0701 0.151913 1.5708 -0 1.5708</pose>
        <geometry>
          <mesh>
            <scale>0.001 0.001 0.001</scale>
            <uri>file://iCub/meshes/simmechanics/sim_sea_2-5_l_hip_2_prt-binary.stl</uri>
          </mesh>
        </geometry>
        <material>
          <diffuse>1 1 1 1</diffuse>
        </material>
      </visual>
    </link>
    <joint name='l_hip_roll' type='revolute'>
      <child>l_hip_2</child>
      <parent>l_hip_1</parent>
      <axis>
        <xyz>1 0 0</xyz>
        <limit>
          <lower>-0.349066</lower>
          <upper>2.0944</upper>
          <effort>37</effort>
          <velocity>7.64</velocity>
        </limit>
        <dynamics>
          <damping>1</damping>
          <friction>0</friction>
          <spring_reference>0</spring_reference>
          <spring_stiffness>0</spring_stiffness>
        </dynamics>
        <use_parent_model_frame>0</use_parent_model_frame>
      </axis>
      <physics>
        <ode>
          <implicit_spring_damper>1</implicit_spring_damper>
          <cfm_damping>1</cfm_damping>
          <limit>
            <cfm>0</cfm>
            <erp>0.2</erp>
          </limit>
        </ode>
      </physics>
    </joint>
    <link name='l_hip_3'>
      <pose>0.007309 -0.0701 -0.194213 -3.14159 -0 3.14159</pose>
      <inertial>
        <pose>-0.000123 -0.000282 0.008718 -1.5708 -0 -1.5708</pose>
        <mass>0.126212</mass>
        <inertia>
          <ixx>0.01</ixx>
          <ixy>2.67901e-07</ixy>
          <ixz>-4.41463e-09</ixz>
          <iyy>0.01</iyy>
          <iyz>3.32338e-08</iyz>
          <izz>0.01</izz>
        </inertia>
      </inertial>
      <collision name='l_hip_3_collision'>
        <pose>0.043709 0.0701 -0.226213 -1.5708 -0 -1.5708</pose>
        <geometry>
          <mesh>
            <scale>0.001 0.001 0.001</scale>
            <uri>file://iCub/meshes/simmechanics/sim_sea_2-5_l_upper_thigh_prt-binary.stl</uri>
          </mesh>
        </geometry>
      </collision>
      <visual name='l_hip_3_visual'>
        <pose>0.043709 0.0701 -0.226213 -1.5708 -0 -1.5708</pose>
        <geometry>
          <mesh>
            <scale>0.001 0.001 0.001</scale>
            <uri>file://iCub/meshes/simmechanics/sim_sea_2-5_l_upper_thigh_prt-binary.stl</uri>
          </mesh>
        </geometry>
        <material>
          <diffuse>1 1 1 1</diffuse>
        </material>
      </visual>
    </link>
    <joint name='l_leg_ft_sensor' type='revolute'>
      <child>l_hip_3</child>
      <parent>l_hip_2</parent>
      <axis>
        <limit>
          <lower>0</lower>
          <upper>0</upper>
        </limit>
        <dynamics>
          <damping>0</damping>
          <friction>0</friction>
          <spring_reference>0</spring_reference>
          <spring_stiffness>0</spring_stiffness>
        </dynamics>
        <xyz>0 0 1</xyz>
        <use_parent_model_frame>0</use_parent_model_frame>
      </axis>
      <physics>
        <ode>
          <limit>
            <cfm>0</cfm>
            <erp>0.2</erp>
          </limit>
        </ode>
      </physics>
    </joint>
    <link name='l_upper_leg'>
      <pose>0.007309 -0.0701 -0.208613 0 -0 3.14159</pose>
      <inertial>
        <pose>0.003387 0.000102 -0.078916 1.5708 -0 1.5708</pose>
        <mass>1.8084</mass>
        <inertia>
          <ixx>0.00648513</ixx>
          <ixy>-0.000124211</ixy>
          <ixz>-3.97399e-06</ixz>
          <iyy>0.00146251</iyy>
          <iyz>-0.000136818</iyz>
          <izz>0.00647619</izz>
        </inertia>
      </inertial>
      <collision name='l_upper_leg_collision'>
        <pose>0.043709 -0.0701 0.240813 1.5708 -0 1.5708</pose>
        <geometry>
          <mesh>
            <scale>0.001 0.001 0.001</scale>
            <uri>file://iCub/meshes/simmechanics/sim_sea_2-5_l_thigh_prt-binary.stl</uri>
          </mesh>
        </geometry>
        <surface>
          <contact>
            <ode/>
          </contact>
          <friction>
            <ode/>
          </friction>
        </surface>
      </collision>
      <visual name='l_upper_leg_visual'>
        <pose>0.043709 -0.0701 0.240813 1.5708 -0 1.5708</pose>
        <geometry>
          <mesh>
            <scale>0.001 0.001 0.001</scale>
            <uri>file://iCub/meshes/simmechanics/sim_sea_2-5_l_thigh_prt-binary.stl</uri>
          </mesh>
        </geometry>
        <material>
          <diffuse>1 1 1 1</diffuse>
        </material>
      </visual>
    </link>
    <joint name='l_hip_yaw' type='revolute'>
      <child>l_upper_leg</child>
      <parent>l_hip_3</parent>
      <axis>
        <xyz>0 0 1</xyz>
        <limit>
          <lower>-1.39626</lower>
          <upper>1.39626</upper>
          <effort>37</effort>
          <velocity>7.64</velocity>
        </limit>
        <dynamics>
          <damping>1</damping>
          <friction>0</friction>
          <spring_reference>0</spring_reference>
          <spring_stiffness>0</spring_stiffness>
        </dynamics>
        <use_parent_model_frame>0</use_parent_model_frame>
      </axis>
      <physics>
        <ode>
          <implicit_spring_damper>1</implicit_spring_damper>
          <cfm_damping>1</cfm_damping>
          <limit>
            <cfm>0</cfm>
            <erp>0.2</erp>
          </limit>
        </ode>
      </physics>
    </joint>
    <link name='l_lower_leg'>
      <pose>0.007309 -0.0701 -0.354438 0 -0 3.14159</pose>
      <inertial>
        <pose>0.001 0.003497 -0.088567 1.5708 -0 1.5708</pose>
        <mass>1.4724</mass>
        <inertia>
          <ixx>0.00423699</ixx>
          <ixy>-0.000239615</ixy>
          <ixz>6.76166e-05</ixz>
          <iyy>0.00152221</iyy>
          <iyz>-0.000233143</iyz>
          <izz>0.00457007</izz>
        </inertia>
      </inertial>
      <collision name='l_lower_leg_collision'>
        <pose>0.043709 -0.0701 0.386638 1.5708 -0 1.5708</pose>
        <geometry>
          <mesh>
            <scale>0.001 0.001 0.001</scale>
            <uri>file://iCub/meshes/simmechanics/sim_sea_2-5_l_shank_prt-binary.stl</uri>
          </mesh>
        </geometry>
        <surface>
          <contact>
            <ode/>
          </contact>
          <friction>
            <ode/>
          </friction>
        </surface>
      </collision>
      <visual name='l_lower_leg_visual'>
        <pose>0.043709 -0.0701 0.386638 1.5708 -0 1.5708</pose>
        <geometry>
          <mesh>
            <scale>0.001 0.001 0.001</scale>
            <uri>file://iCub/meshes/simmechanics/sim_sea_2-5_l_shank_prt-binary.stl</uri>
          </mesh>
        </geometry>
        <material>
          <diffuse>1 1 1 1</diffuse>
        </material>
      </visual>
      <velocity_decay/>
    </link>
    <joint name='l_knee' type='revolute'>
      <child>l_lower_leg</child>
      <parent>l_upper_leg</parent>
      <axis>
        <xyz>-0 -1 0</xyz>
        <limit>
          <lower>-2.16421</lower>
          <upper>0.0698132</upper>
          <effort>37</effort>
          <velocity>7.64</velocity>
        </limit>
        <dynamics>
          <damping>1</damping>
          <friction>0</friction>
          <spring_reference>0</spring_reference>
          <spring_stiffness>0</spring_stiffness>
        </dynamics>
        <use_parent_model_frame>0</use_parent_model_frame>
      </axis>
      <physics>
        <ode>
          <implicit_spring_damper>1</implicit_spring_damper>
          <cfm_damping>1</cfm_damping>
          <limit>
            <cfm>0</cfm>
            <erp>0.2</erp>
          </limit>
        </ode>
      </physics>
    </joint>
    <link name='l_ankle_1'>
      <pose>0.007309 -0.0701 -0.554938 0 -0 3.14159</pose>
      <inertial>
        <pose>0.015153 0.000902 4.2e-05 1.5708 -0 1.5708</pose>
        <mass>0.6798</mass>
        <inertia>
          <ixx>0.000404474</ixx>
          <ixy>-1.13226e-06</ixy>
          <ixz>3.04665e-05</ixz>
          <iyy>0.000447887</iyy>
          <iyz>2.57266e-06</iyz>
          <izz>0.000307603</izz>
        </inertia>
      </inertial>
      <collision name='l_ankle_1_collision'>
        <pose>0.043709 -0.0701 0.587138 1.5708 -0 1.5708</pose>
        <geometry>
          <mesh>
            <scale>0.001 0.001 0.001</scale>
            <uri>file://iCub/meshes/simmechanics/sim_sea_2-5_l_ankle_prt-binary.stl</uri>
          </mesh>
        </geometry>
      </collision>
      <visual name='l_ankle_1_visual'>
        <pose>0.043709 -0.0701 0.587138 1.5708 -0 1.5708</pose>
        <geometry>
          <mesh>
            <scale>0.001 0.001 0.001</scale>
            <uri>file://iCub/meshes/simmechanics/sim_sea_2-5_l_ankle_prt-binary.stl</uri>
          </mesh>
        </geometry>
        <material>
          <diffuse>1 1 1 1</diffuse>
        </material>
      </visual>
    </link>
    <joint name='l_ankle_pitch' type='revolute'>
      <child>l_ankle_1</child>
      <parent>l_lower_leg</parent>
      <axis>
        <xyz>0 1 0</xyz>
        <limit>
          <lower>-0.610865</lower>
          <upper>0.610865</upper>
          <effort>37</effort>
          <velocity>7.64</velocity>
        </limit>
        <dynamics>
          <damping>1</damping>
          <friction>0</friction>
          <spring_reference>0</spring_reference>
          <spring_stiffness>0</spring_stiffness>
        </dynamics>
        <use_parent_model_frame>0</use_parent_model_frame>
      </axis>
      <physics>
        <ode>
          <implicit_spring_damper>1</implicit_spring_damper>
          <cfm_damping>1</cfm_damping>
          <limit>
            <cfm>0</cfm>
            <erp>0.2</erp>
          </limit>
        </ode>
      </physics>
    </joint>
    <link name='l_ankle_2'>
      <pose>0.007309 -0.0701 -0.554938 0 -0 3.14159</pose>
      <inertial>
        <pose>0.000767 -8e-06 -0.038202 1.5708 -0 1.5708</pose>
        <mass>0.267485</mass>
        <inertia>
          <ixx>0.01</ixx>
          <ixy>-7.53335e-08</ixy>
          <ixz>2.93681e-08</ixz>
          <iyy>0.01</iyy>
          <iyz>-4.26218e-07</iyz>
          <izz>0.01</izz>
        </inertia>
      </inertial>
      <collision name='l_ankle_2_collision'>
        <pose>0.043709 -0.0701 0.587138 1.5708 -0 1.5708</pose>
        <geometry>
          <mesh>
            <scale>0.001 0.001 0.001</scale>
            <uri>file://iCub/meshes/simmechanics/sim_sea_2-5_l_foot_prt-binary.stl</uri>
          </mesh>
        </geometry>
      </collision>
      <visual name='l_ankle_2_visual'>
        <pose>0.043709 -0.0701 0.587138 1.5708 -0 1.5708</pose>
        <geometry>
          <mesh>
            <scale>0.001 0.001 0.001</scale>
            <uri>file://iCub/meshes/simmechanics/sim_sea_2-5_l_foot_prt-binary.stl</uri>
          </mesh>
        </geometry>
        <material>
          <diffuse>1 1 1 1</diffuse>
        </material>
      </visual>
    </link>
    <joint name='l_ankle_roll' type='revolute'>
      <child>l_ankle_2</child>
      <parent>l_ankle_1</parent>
      <axis>
        <xyz>1 0 0</xyz>
        <limit>
          <lower>-0.436332</lower>
          <upper>0.436332</upper>
          <effort>37</effort>
          <velocity>7.64</velocity>
        </limit>
        <dynamics>
          <damping>1</damping>
          <friction>0</friction>
          <spring_reference>0</spring_reference>
          <spring_stiffness>0</spring_stiffness>
        </dynamics>
        <use_parent_model_frame>0</use_parent_model_frame>
      </axis>
      <physics>
        <ode>
          <implicit_spring_damper>1</implicit_spring_damper>
          <cfm_damping>1</cfm_damping>
          <limit>
            <cfm>0</cfm>
            <erp>0.2</erp>
          </limit>
        </ode>
      </physics>
    </joint>
    <link name='l_foot'>
      <pose>0.010809 -0.0701 -0.615438 -3.14159 -0 3.14159</pose>
      <inertial>
        <pose>0.033667 -0.005374 -0.001164 -1.5708 -0 -1.5708</pose>
        <mass>0.382968</mass>
        <inertia>
          <ixx>0.00121242</ixx>
          <ixy>-3.69533e-07</ixy>
          <ixz>5.79273e-05</ixz>
          <iyy>0.00141712</iyy>
          <iyz>-7.64972e-06</iyz>
          <izz>0.000273846</izz>
        </inertia>
      </inertial>
      <collision name='l_foot_collision'>
        <pose>0.03 -0.005 0.014 0 -0 0</pose>
        <geometry>
          <box>
            <size>0.16 0.072 0.001</size>
          </box>
        </geometry>
        <surface>
          <bounce>
            <restitution_coefficient>0</restitution_coefficient>
            <threshold>100000</threshold>
          </bounce>
          <contact>
            <ode>
              <kp>1.8e+07</kp>
              <kd>100</kd>
              <max_vel>100</max_vel>
              <min_depth>0.0001</min_depth>
            </ode>
          </contact>
          <friction>
            <ode>
              <mu>1</mu>
              <mu2>1</mu2>
              <fdir1>0 0 0</fdir1>
            </ode>
          </friction>
        </surface>
        <max_contacts>4</max_contacts>
      </collision>
      <visual name='l_foot_visual'>
        <pose>0.047209 0.0701 -0.647438 -1.5708 -0 -1.5708</pose>
        <geometry>
          <mesh>
            <scale>0.001 0.001 0.001</scale>
            <uri>file://iCub/meshes/simmechanics/sim_sea_2-5_l_sole_prt-binary.stl</uri>
          </mesh>
        </geometry>
        <material>
          <diffuse>1 1 1 1</diffuse>
        </material>
      </visual>
      <velocity_decay/>
      <velocity_decay/>
    </link>
    <joint name='l_foot_ft_sensor' type='revolute'>
      <child>l_foot</child>
      <parent>l_ankle_2</parent>
      <axis>
        <limit>
          <lower>0</lower>
          <upper>0</upper>
        </limit>
        <dynamics>
          <damping>0</damping>
          <friction>0</friction>
          <spring_reference>0</spring_reference>
          <spring_stiffness>0</spring_stiffness>
        </dynamics>
        <xyz>0 0 1</xyz>
        <use_parent_model_frame>0</use_parent_model_frame>
      </axis>
      <physics>
        <ode>
          <limit>
            <cfm>0</cfm>
            <erp>0.2</erp>
          </limit>
        </ode>
      </physics>
    </joint>
    <link name='r_hip_1'>
      <pose>0.006452 0.026 -0.119913 0 -0 3.14159</pose>
      <inertial>
        <pose>-0.000515 -0.038075 -7.1e-05 1.5708 -0 1.5708</pose>
        <mass>0.919978</mass>
        <inertia>
          <ixx>0.000404268</ixx>
          <ixy>-1.26852e-06</ixy>
          <ixz>1.11055e-06</ixz>
          <iyy>0.000574741</iyy>
          <iyz>-7.69474e-07</iyz>
          <izz>0.000580025</izz>
        </inertia>
      </inertial>
      <collision name='r_hip_1_collision'>
        <pose>0.042852 0.026 0.151913 1.5708 -0 1.5708</pose>
        <geometry>
          <mesh>
            <scale>0.001 0.001 0.001</scale>
            <uri>file://iCub/meshes/simmechanics/sim_sea_2-5_r_hip_1_prt-binary.stl</uri>
          </mesh>
        </geometry>
      </collision>
      <visual name='r_hip_1_visual'>
        <pose>0.042852 0.026 0.151913 1.5708 -0 1.5708</pose>
        <geometry>
          <mesh>
            <scale>0.001 0.001 0.001</scale>
            <uri>file://iCub/meshes/simmechanics/sim_sea_2-5_r_hip_1_prt-binary.stl</uri>
          </mesh>
        </geometry>
        <material>
          <diffuse>1 1 1 1</diffuse>
        </material>
      </visual>
    </link>
    <joint name='r_hip_pitch' type='revolute'>
      <child>r_hip_1</child>
      <parent>base_link</parent>
      <axis>
        <xyz>-0 -1 0</xyz>
        <limit>
          <lower>-0.785398</lower>
          <upper>2.33874</upper>
          <effort>55.5</effort>
          <velocity>5.1</velocity>
        </limit>
        <dynamics>
          <damping>1</damping>
          <friction>0</friction>
          <spring_reference>0</spring_reference>
          <spring_stiffness>0</spring_stiffness>
        </dynamics>
        <use_parent_model_frame>0</use_parent_model_frame>
      </axis>
      <physics>
        <ode>
          <implicit_spring_damper>1</implicit_spring_damper>
          <cfm_damping>1</cfm_damping>
          <limit>
            <cfm>0</cfm>
            <erp>0.2</erp>
          </limit>
        </ode>
      </physics>
    </joint>
    <link name='r_hip_2'>
      <pose>0.006452 0.0701 -0.119913 0 -0 3.14159</pose>
      <inertial>
        <pose>-0.001375 4e-06 -0.044282 1.5708 -0 1.5708</pose>
        <mass>0.418361</mass>
        <inertia>
          <ixx>0.000487866</ixx>
          <ixy>-2.70231e-07</ixy>
          <ixz>1.85338e-07</ixz>
          <iyy>0.000286099</iyy>
          <iyz>1.22793e-05</iyz>
          <izz>0.000315174</izz>
        </inertia>
      </inertial>
      <collision name='r_hip_2_collision'>
        <pose>0.042852 0.0701 0.151913 1.5708 -0 1.5708</pose>
        <geometry>
          <mesh>
            <scale>0.001 0.001 0.001</scale>
            <uri>file://iCub/meshes/simmechanics/sim_sea_2-5_r_hip_2_prt-binary.stl</uri>
          </mesh>
        </geometry>
      </collision>
      <visual name='r_hip_2_visual'>
        <pose>0.042852 0.0701 0.151913 1.5708 -0 1.5708</pose>
        <geometry>
          <mesh>
            <scale>0.001 0.001 0.001</scale>
            <uri>file://iCub/meshes/simmechanics/sim_sea_2-5_r_hip_2_prt-binary.stl</uri>
          </mesh>
        </geometry>
        <material>
          <diffuse>1 1 1 1</diffuse>
        </material>
      </visual>
    </link>
    <joint name='r_hip_roll' type='revolute'>
      <child>r_hip_2</child>
      <parent>r_hip_1</parent>
      <axis>
        <xyz>-1 0 -0</xyz>
        <limit>
          <lower>-0.349066</lower>
          <upper>2.0944</upper>
          <effort>37</effort>
          <velocity>7.64</velocity>
        </limit>
        <dynamics>
          <damping>1</damping>
          <friction>0</friction>
          <spring_reference>0</spring_reference>
          <spring_stiffness>0</spring_stiffness>
        </dynamics>
        <use_parent_model_frame>0</use_parent_model_frame>
      </axis>
      <physics>
        <ode>
          <implicit_spring_damper>1</implicit_spring_damper>
          <cfm_damping>1</cfm_damping>
          <limit>
            <cfm>0</cfm>
            <erp>0.2</erp>
          </limit>
        </ode>
      </physics>
    </joint>
    <link name='r_hip_3'>
      <pose>0.007309 0.0701 -0.194213 -3.14159 -0 3.14159</pose>
      <inertial>
        <pose>-0.000123 -0.000282 0.008718 -1.5708 -0 -1.5708</pose>
        <mass>0.126212</mass>
        <inertia>
          <ixx>0.01</ixx>
          <ixy>2.67901e-07</ixy>
          <ixz>-4.41463e-09</ixz>
          <iyy>0.01</iyy>
          <iyz>3.32338e-08</iyz>
          <izz>0.01</izz>
        </inertia>
      </inertial>
      <collision name='r_hip_3_collision'>
        <pose>0.043709 -0.0701 -0.226213 -1.5708 -0 -1.5708</pose>
        <geometry>
          <mesh>
            <scale>0.001 0.001 0.001</scale>
            <uri>file://iCub/meshes/simmechanics/sim_sea_2-5_r_upper_thigh_prt-binary.stl</uri>
          </mesh>
        </geometry>
      </collision>
      <visual name='r_hip_3_visual'>
        <pose>0.043709 -0.0701 -0.226213 -1.5708 -0 -1.5708</pose>
        <geometry>
          <mesh>
            <scale>0.001 0.001 0.001</scale>
            <uri>file://iCub/meshes/simmechanics/sim_sea_2-5_r_upper_thigh_prt-binary.stl</uri>
          </mesh>
        </geometry>
        <material>
          <diffuse>1 1 1 1</diffuse>
        </material>
      </visual>
    </link>
    <joint name='r_leg_ft_sensor' type='revolute'>
      <child>r_hip_3</child>
      <parent>r_hip_2</parent>
      <axis>
        <limit>
          <lower>0</lower>
          <upper>0</upper>
        </limit>
        <dynamics>
          <damping>0</damping>
          <friction>0</friction>
          <spring_reference>0</spring_reference>
          <spring_stiffness>0</spring_stiffness>
        </dynamics>
        <xyz>0 0 1</xyz>
        <use_parent_model_frame>0</use_parent_model_frame>
      </axis>
      <physics>
        <ode>
          <limit>
            <cfm>0</cfm>
            <erp>0.2</erp>
          </limit>
        </ode>
      </physics>
    </joint>
    <link name='r_upper_leg'>
      <pose>0.007309 0.0701 -0.208613 0 -0 3.14159</pose>
      <inertial>
        <pose>0.0034 -2.9e-05 -0.078954 1.5708 -0 1.5708</pose>
        <mass>1.8035</mass>
        <inertia>
          <ixx>0.00647751</ixx>
          <ixy>0.000129579</ixy>
          <ixz>5.48205e-06</ixz>
          <iyy>0.00145938</iyy>
          <iyz>-0.000136613</iyz>
          <izz>0.00646721</izz>
        </inertia>
      </inertial>
      <collision name='r_upper_leg_collision'>
        <pose>0.043709 0.0701 0.240813 1.5708 -0 1.5708</pose>
        <geometry>
          <mesh>
            <scale>0.001 0.001 0.001</scale>
            <uri>file://iCub/meshes/simmechanics/sim_sea_2-5_r_thigh_prt-binary.stl</uri>
          </mesh>
        </geometry>
        <surface>
          <contact>
            <ode/>
          </contact>
          <friction>
            <ode/>
          </friction>
        </surface>
      </collision>
      <visual name='r_upper_leg_visual'>
        <pose>0.043709 0.0701 0.240813 1.5708 -0 1.5708</pose>
        <geometry>
          <mesh>
            <scale>0.001 0.001 0.001</scale>
            <uri>file://iCub/meshes/simmechanics/sim_sea_2-5_r_thigh_prt-binary.stl</uri>
          </mesh>
        </geometry>
        <material>
          <diffuse>1 1 1 1</diffuse>
        </material>
      </visual>
      <velocity_decay/>
    </link>
    <joint name='r_hip_yaw' type='revolute'>
      <child>r_upper_leg</child>
      <parent>r_hip_3</parent>
      <axis>
        <xyz>0 -0 -1</xyz>
        <limit>
          <lower>-1.39626</lower>
          <upper>1.39626</upper>
          <effort>37</effort>
          <velocity>7.64</velocity>
        </limit>
        <dynamics>
          <damping>1</damping>
          <friction>0</friction>
          <spring_reference>0</spring_reference>
          <spring_stiffness>0</spring_stiffness>
        </dynamics>
        <use_parent_model_frame>0</use_parent_model_frame>
      </axis>
      <physics>
        <ode>
          <implicit_spring_damper>1</implicit_spring_damper>
          <cfm_damping>1</cfm_damping>
          <limit>
            <cfm>0</cfm>
            <erp>0.2</erp>
          </limit>
        </ode>
      </physics>
    </joint>
    <link name='r_lower_leg'>
      <pose>0.007309 0.0701 -0.354438 0 -0 3.14159</pose>
      <inertial>
        <pose>0.001236 -0.003513 -0.088794 1.5708 -0 1.5708</pose>
        <mass>1.472</mass>
        <inertia>
          <ixx>0.00423993</ixx>
          <ixy>0.000228815</ixy>
          <ixz>-5.55646e-05</ixz>
          <iyy>0.00152095</iyy>
          <iyz>-0.000264133</iyz>
          <izz>0.00457359</izz>
        </inertia>
      </inertial>
      <collision name='r_lower_leg_collision'>
        <pose>0.043709 0.0701 0.386638 1.5708 -0 1.5708</pose>
        <geometry>
          <mesh>
            <scale>0.001 0.001 0.001</scale>
            <uri>file://iCub/meshes/simmechanics/sim_sea_2-5_r_shank_prt-binary.stl</uri>
          </mesh>
        </geometry>
        <surface>
          <contact>
            <ode/>
          </contact>
          <friction>
            <ode/>
          </friction>
        </surface>
      </collision>
      <visual name='r_lower_leg_visual'>
        <pose>0.043709 0.0701 0.386638 1.5708 -0 1.5708</pose>
        <geometry>
          <mesh>
            <scale>0.001 0.001 0.001</scale>
            <uri>file://iCub/meshes/simmechanics/sim_sea_2-5_r_shank_prt-binary.stl</uri>
          </mesh>
        </geometry>
        <material>
          <diffuse>1 1 1 1</diffuse>
        </material>
      </visual>
      <velocity_decay/>
    </link>
    <joint name='r_knee' type='revolute'>
      <child>r_lower_leg</child>
      <parent>r_upper_leg</parent>
      <axis>
        <xyz>-0 -1 0</xyz>
        <limit>
          <lower>-2.16421</lower>
          <upper>0.0698132</upper>
          <effort>37</effort>
          <velocity>7.64</velocity>
        </limit>
        <dynamics>
          <damping>1</damping>
          <friction>0</friction>
          <spring_reference>0</spring_reference>
          <spring_stiffness>0</spring_stiffness>
        </dynamics>
        <use_parent_model_frame>0</use_parent_model_frame>
      </axis>
      <physics>
        <ode>
          <implicit_spring_damper>1</implicit_spring_damper>
          <cfm_damping>1</cfm_damping>
          <limit>
            <cfm>0</cfm>
            <erp>0.2</erp>
          </limit>
        </ode>
      </physics>
    </joint>
    <link name='r_ankle_1'>
      <pose>0.007309 0.0701 -0.554938 0 -0 3.14159</pose>
      <inertial>
        <pose>0.015144 -0.000869 4.2e-05 1.5708 -0 1.5708</pose>
        <mass>0.6803</mass>
        <inertia>
          <ixx>0.000404619</ixx>
          <ixy>7.49819e-07</ixy>
          <ixz>-3.01349e-05</ixz>
          <iyy>0.000448634</iyy>
          <iyz>2.57267e-06</iyz>
          <izz>0.000308236</izz>
        </inertia>
      </inertial>
      <collision name='r_ankle_1_collision'>
        <pose>0.043709 0.0701 0.587138 1.5708 -0 1.5708</pose>
        <geometry>
          <mesh>
            <scale>0.001 0.001 0.001</scale>
            <uri>file://iCub/meshes/simmechanics/sim_sea_2-5_r_ankle_prt-binary.stl</uri>
          </mesh>
        </geometry>
      </collision>
      <visual name='r_ankle_1_visual'>
        <pose>0.043709 0.0701 0.587138 1.5708 -0 1.5708</pose>
        <geometry>
          <mesh>
            <scale>0.001 0.001 0.001</scale>
            <uri>file://iCub/meshes/simmechanics/sim_sea_2-5_r_ankle_prt-binary.stl</uri>
          </mesh>
        </geometry>
        <material>
          <diffuse>1 1 1 1</diffuse>
        </material>
      </visual>
    </link>
    <joint name='r_ankle_pitch' type='revolute'>
      <child>r_ankle_1</child>
      <parent>r_lower_leg</parent>
      <axis>
        <xyz>0 1 0</xyz>
        <limit>
          <lower>-0.610865</lower>
          <upper>0.610865</upper>
          <effort>37</effort>
          <velocity>7.64</velocity>
        </limit>
        <dynamics>
          <damping>1</damping>
          <friction>0</friction>
          <spring_reference>0</spring_reference>
          <spring_stiffness>0</spring_stiffness>
        </dynamics>
        <use_parent_model_frame>0</use_parent_model_frame>
      </axis>
      <physics>
        <ode>
          <implicit_spring_damper>1</implicit_spring_damper>
          <cfm_damping>1</cfm_damping>
          <limit>
            <cfm>0</cfm>
            <erp>0.2</erp>
          </limit>
        </ode>
      </physics>
    </joint>
    <link name='r_ankle_2'>
      <pose>0.007309 0.0701 -0.554938 0 -0 3.14159</pose>
      <inertial>
        <pose>0.000767 -8e-06 -0.038202 1.5708 -0 1.5708</pose>
        <mass>0.267485</mass>
        <inertia>
          <ixx>0.01</ixx>
          <ixy>-7.53335e-08</ixy>
          <ixz>2.93681e-08</ixz>
          <iyy>0.01</iyy>
          <iyz>-4.26218e-07</iyz>
          <izz>0.01</izz>
        </inertia>
      </inertial>
      <collision name='r_ankle_2_collision'>
        <pose>0.043709 0.0701 0.587138 1.5708 -0 1.5708</pose>
        <geometry>
          <mesh>
            <scale>0.001 0.001 0.001</scale>
            <uri>file://iCub/meshes/simmechanics/sim_sea_2-5_r_foot_prt-binary.stl</uri>
          </mesh>
        </geometry>
      </collision>
      <visual name='r_ankle_2_visual'>
        <pose>0.043709 0.0701 0.587138 1.5708 -0 1.5708</pose>
        <geometry>
          <mesh>
            <scale>0.001 0.001 0.001</scale>
            <uri>file://iCub/meshes/simmechanics/sim_sea_2-5_r_foot_prt-binary.stl</uri>
          </mesh>
        </geometry>
        <material>
          <diffuse>1 1 1 1</diffuse>
        </material>
      </visual>
    </link>
    <joint name='r_ankle_roll' type='revolute'>
      <child>r_ankle_2</child>
      <parent>r_ankle_1</parent>
      <axis>
        <xyz>-1 0 -0</xyz>
        <limit>
          <lower>-0.436332</lower>
          <upper>0.436332</upper>
          <effort>37</effort>
          <velocity>7.64</velocity>
        </limit>
        <dynamics>
          <damping>1</damping>
          <friction>0</friction>
          <spring_reference>0</spring_reference>
          <spring_stiffness>0</spring_stiffness>
        </dynamics>
        <use_parent_model_frame>0</use_parent_model_frame>
      </axis>
      <physics>
        <ode>
          <implicit_spring_damper>1</implicit_spring_damper>
          <cfm_damping>1</cfm_damping>
          <limit>
            <cfm>0</cfm>
            <erp>0.2</erp>
          </limit>
        </ode>
      </physics>
    </joint>
    <link name='r_foot'>
      <pose>0.010809 0.0701 -0.615438 -3.14159 -0 3.14159</pose>
      <inertial>
        <pose>0.0336 0.005372 -0.001147 -1.5708 -0 -1.5708</pose>
        <mass>0.382866</mass>
        <inertia>
          <ixx>0.00120946</ixx>
          <ixy>3.74585e-07</ixy>
          <ixz>-5.78759e-05</ixz>
          <iyy>0.00141439</iyy>
          <iyz>-7.80325e-06</iyz>
          <izz>0.000273599</izz>
        </inertia>
      </inertial>
      <collision name='r_foot_collision'>
        <pose>0.03 0.005 0.014 0 -0 0</pose>
        <geometry>
          <box>
            <size>0.16 0.072 0.001</size>
          </box>
        </geometry>
        <surface>
          <bounce>
            <restitution_coefficient>0</restitution_coefficient>
            <threshold>100000</threshold>
          </bounce>
          <contact>
            <ode>
              <kp>1.8e+07</kp>
              <kd>100</kd>
              <max_vel>100</max_vel>
              <min_depth>0.0001</min_depth>
            </ode>
          </contact>
          <friction>
            <ode>
              <mu>1</mu>
              <mu2>1</mu2>
              <fdir1>0 0 0</fdir1>
            </ode>
          </friction>
        </surface>
        <max_contacts>4</max_contacts>
      </collision>
      <visual name='r_foot_visual'>
        <pose>0.047209 -0.0701 -0.647438 -1.5708 -0 -1.5708</pose>
        <geometry>
          <mesh>
            <scale>0.001 0.001 0.001</scale>
            <uri>file://iCub/meshes/simmechanics/sim_sea_2-5_r_sole_prt-binary.stl</uri>
          </mesh>
        </geometry>
        <material>
          <diffuse>1 1 1 1</diffuse>
        </material>
      </visual>
      <velocity_decay/>
      <velocity_decay/>
    </link>
    <joint name='r_foot_ft_sensor' type='revolute'>
      <child>r_foot</child>
      <parent>r_ankle_2</parent>
      <axis>
        <limit>
          <lower>0</lower>
          <upper>0</upper>
        </limit>
        <dynamics>
          <damping>0</damping>
          <friction>0</friction>
          <spring_reference>0</spring_reference>
          <spring_stiffness>0</spring_stiffness>
        </dynamics>
        <xyz>0 0 1</xyz>
        <use_parent_model_frame>0</use_parent_model_frame>
      </axis>
      <physics>
        <ode>
          <limit>
            <cfm>0</cfm>
            <erp>0.2</erp>
          </limit>
        </ode>
      </physics>
    </joint>
    <link name='torso_1'>
      <pose>0 0.027046 0 1.5708 0 -1.5708</pose>
      <inertial>
        <pose>0.027092 0.029148 -0.00044 0 -0 0</pose>
        <mass>0.67144</mass>
        <inertia>
          <ixx>0.00040911</ixx>
          <ixy>-1.04522e-06</ixy>
          <ixz>-1.02516e-06</ixz>
          <iyy>0.000384141</iyy>
          <iyz>6.50708e-06</iyz>
          <izz>0.000299445</izz>
        </inertia>
      </inertial>
      <collision name='torso_1_collision'>
        <pose>0.027046 0.032 0.0364 0 -0 0</pose>
        <geometry>
          <mesh>
            <scale>0.001 0.001 0.001</scale>
            <uri>file://iCub/meshes/simmechanics/sim_sea_2-5_lap_belt_1_prt-binary.stl</uri>
          </mesh>
        </geometry>
      </collision>
      <visual name='torso_1_visual'>
        <pose>0.027046 0.032 0.0364 0 -0 0</pose>
        <geometry>
          <mesh>
            <scale>0.001 0.001 0.001</scale>
            <uri>file://iCub/meshes/simmechanics/sim_sea_2-5_lap_belt_1_prt-binary.stl</uri>
          </mesh>
        </geometry>
        <material>
          <diffuse>1 1 1 1</diffuse>
        </material>
      </visual>
    </link>
    <joint name='torso_pitch' type='revolute'>
      <child>torso_1</child>
      <parent>base_link</parent>
      <axis>
        <xyz>1 0 0</xyz>
        <limit>
          <lower>-0.349066</lower>
          <upper>1.22173</upper>
          <effort>50000</effort>
          <velocity>50000</velocity>
        </limit>
        <dynamics>
          <damping>1</damping>
          <friction>0</friction>
          <spring_reference>0</spring_reference>
          <spring_stiffness>0</spring_stiffness>
        </dynamics>
        <use_parent_model_frame>0</use_parent_model_frame>
      </axis>
      <physics>
        <ode>
          <implicit_spring_damper>1</implicit_spring_damper>
          <cfm_damping>1</cfm_damping>
          <limit>
            <cfm>0</cfm>
            <erp>0.2</erp>
          </limit>
        </ode>
      </physics>
    </joint>
    <link name='torso_2'>
      <pose>0.057345 0 0.032 1.5708 0 -1.5708</pose>
      <inertial>
        <pose>-0.000114 0.036153 0.057096 0 -0 0</pose>
        <mass>0.425685</mass>
        <inertia>
          <ixx>0.000829234</ixx>
          <ixy>2.37006e-08</ixy>
          <ixz>9.25231e-08</ixz>
          <iyy>0.000436517</iyy>
          <iyz>-1.74814e-07</iyz>
          <izz>0.000604802</izz>
        </inertia>
      </inertial>
      <collision name='torso_2_collision'>
        <pose>0 0.1433 0.038653 0 -0 0</pose>
        <geometry>
          <mesh>
            <scale>0.001 0.001 0.001</scale>
            <uri>file://iCub/meshes/simmechanics/sim_sea_2-5_lap_belt_2_prt-binary.stl</uri>
          </mesh>
        </geometry>
      </collision>
      <visual name='torso_2_visual'>
        <pose>0 0.1433 0.038653 0 -0 0</pose>
        <geometry>
          <mesh>
            <scale>0.001 0.001 0.001</scale>
            <uri>file://iCub/meshes/simmechanics/sim_sea_2-5_lap_belt_2_prt-binary.stl</uri>
          </mesh>
        </geometry>
        <material>
          <diffuse>1 1 1 1</diffuse>
        </material>
      </visual>
    </link>
    <joint name='torso_roll' type='revolute'>
      <child>torso_2</child>
      <parent>torso_1</parent>
      <axis>
        <xyz>0 0 -1</xyz>
        <limit>
          <lower>-0.523599</lower>
          <upper>0.523599</upper>
          <effort>50000</effort>
          <velocity>50000</velocity>
        </limit>
        <dynamics>
          <damping>1</damping>
          <friction>0</friction>
          <spring_reference>0</spring_reference>
          <spring_stiffness>0</spring_stiffness>
        </dynamics>
        <use_parent_model_frame>0</use_parent_model_frame>
      </axis>
      <physics>
        <ode>
          <implicit_spring_damper>1</implicit_spring_damper>
          <cfm_damping>1</cfm_damping>
          <limit>
            <cfm>0</cfm>
            <erp>0.2</erp>
          </limit>
        </ode>
      </physics>
    </joint>
    <link name='chest'>
      <pose>-0.005498 0 0.082 1.5708 0 -1.5708</pose>
      <inertial>
        <pose>0.000189 0.073091 -0.047238 0 -0 0</pose>
        <mass>7.638</mass>
        <inertia>
          <ixx>0.0430325</ixx>
          <ixy>2.91075e-05</ixy>
          <ixz>0.000181985</ixz>
          <iyy>0.0440836</iyy>
          <iyz>-0.000429106</iyz>
          <izz>0.0260563</izz>
        </inertia>
      </inertial>
      <collision name='chest_collision'>
        <pose>0 0.0928 -0.024189 0 -0 0</pose>
        <geometry>
          <mesh>
            <scale>0.001 0.001 0.001</scale>
            <uri>file://iCub/meshes/simmechanics/sim_sea_2-5_chest_bb_prt-binary.stl</uri>
          </mesh>
        </geometry>
        <surface>
          <contact>
            <ode/>
          </contact>
          <friction>
            <ode/>
          </friction>
        </surface>
      </collision>
      <visual name='chest_visual'>
        <pose>0 0.0928 -0.024189 0 -0 0</pose>
        <geometry>
          <mesh>
            <scale>0.001 0.001 0.001</scale>
            <uri>file://iCub/meshes/simmechanics/sim_sea_2-5_chest_bb_prt-binary.stl</uri>
          </mesh>
        </geometry>
        <material>
          <diffuse>1 1 1 1</diffuse>
        </material>
      </visual>
      <velocity_decay/>
    </link>
    <joint name='torso_yaw' type='revolute'>
      <child>chest</child>
      <parent>torso_2</parent>
      <axis>
        <xyz>0 -1 0</xyz>
        <limit>
          <lower>-0.872665</lower>
          <upper>0.872665</upper>
          <effort>50000</effort>
          <velocity>50000</velocity>
        </limit>
        <dynamics>
          <damping>1</damping>
          <friction>0</friction>
          <spring_reference>0</spring_reference>
          <spring_stiffness>0</spring_stiffness>
        </dynamics>
        <use_parent_model_frame>0</use_parent_model_frame>
      </axis>
      <physics>
        <ode>
          <implicit_spring_damper>1</implicit_spring_damper>
          <cfm_damping>1</cfm_damping>
          <limit>
            <cfm>0</cfm>
            <erp>0.2</erp>
          </limit>
        </ode>
      </physics>
    </joint>
    <link name='l_shoulder_1'>
      <pose>-0.013467 -0.120016 0.1748 1.5708 0 -1.5708</pose>
      <inertial>
        <pose>-0.008985 -3.3e-05 -0.0089 0 -0 0</pose>
        <mass>0.114882</mass>
        <inertia>
          <ixx>0.01</ixx>
          <ixy>-1.77064e-08</ixy>
          <ixz>3.55951e-06</ixz>
          <iyy>0.01</iyy>
          <iyz>6.57597e-08</iyz>
          <izz>0.01</izz>
        </inertia>
      </inertial>
      <collision name='l_shoulder_1_collision'>
        <pose>-0.120257 0 -0.032223 0 -0 0</pose>
        <geometry>
          <mesh>
            <scale>0.001 0.001 0.001</scale>
            <uri>file://iCub/meshes/simmechanics/sim_sea_2-5_l_shoulder_1_prt-binary.stl</uri>
          </mesh>
        </geometry>
      </collision>
      <visual name='l_shoulder_1_visual'>
        <pose>-0.120257 0 -0.032223 0 -0 0</pose>
        <geometry>
          <mesh>
            <scale>0.001 0.001 0.001</scale>
            <uri>file://iCub/meshes/simmechanics/sim_sea_2-5_l_shoulder_1_prt-binary.stl</uri>
          </mesh>
        </geometry>
        <material>
          <diffuse>1 1 1 1</diffuse>
        </material>
      </visual>
    </link>
    <joint name='l_shoulder_pitch' type='revolute'>
      <child>l_shoulder_1</child>
      <parent>chest</parent>
      <axis>
        <xyz>0.965926 0 0.258819</xyz>
        <limit>
          <lower>-1.66679</lower>
          <upper>0.174533</upper>
          <effort>50000</effort>
          <velocity>50000</velocity>
        </limit>
        <dynamics>
          <damping>1</damping>
          <friction>0</friction>
          <spring_reference>0</spring_reference>
          <spring_stiffness>0</spring_stiffness>
        </dynamics>
        <use_parent_model_frame>0</use_parent_model_frame>
      </axis>
      <physics>
        <ode>
          <implicit_spring_damper>1</implicit_spring_damper>
          <cfm_damping>1</cfm_damping>
          <limit>
            <cfm>0</cfm>
            <erp>0.2</erp>
          </limit>
        </ode>
      </physics>
    </joint>
    <link name='l_shoulder_2'>
      <pose>-0.021987 -0.106345 0.1748 -3.14159 1.309 -0.261799</pose>
      <inertial>
        <pose>0.021475 0.000269 -0.019411 0 -0 0</pose>
        <mass>0.238162</mass>
        <inertia>
          <ixx>0.01</ixx>
          <ixy>1.19701e-07</ixy>
          <ixz>-1.29687e-05</ixz>
          <iyy>0.01</iyy>
          <iyz>1.20112e-06</iyz>
          <izz>0.01</izz>
        </inertia>
      </inertial>
      <collision name='l_shoulder_2_collision'>
        <pose>-0.106587 0 -0.040743 0 -0 0</pose>
        <geometry>
          <mesh>
            <scale>0.001 0.001 0.001</scale>
            <uri>file://iCub/meshes/simmechanics/sim_sea_2-5_l_shoulder_2_prt-binary.stl</uri>
          </mesh>
        </geometry>
      </collision>
      <visual name='l_shoulder_2_visual'>
        <pose>-0.106587 0 -0.040743 0 -0 0</pose>
        <geometry>
          <mesh>
            <scale>0.001 0.001 0.001</scale>
            <uri>file://iCub/meshes/simmechanics/sim_sea_2-5_l_shoulder_2_prt-binary.stl</uri>
          </mesh>
        </geometry>
        <material>
          <diffuse>1 1 1 1</diffuse>
        </material>
      </visual>
    </link>
    <joint name='l_shoulder_roll' type='revolute'>
      <child>l_shoulder_2</child>
      <parent>l_shoulder_1</parent>
      <axis>
        <xyz>-0.258819 0 0.965926</xyz>
        <limit>
          <lower>0</lower>
          <upper>2.80649</upper>
          <effort>50000</effort>
          <velocity>50000</velocity>
        </limit>
        <dynamics>
          <damping>1</damping>
          <friction>0</friction>
          <spring_reference>0</spring_reference>
          <spring_stiffness>0</spring_stiffness>
        </dynamics>
        <use_parent_model_frame>0</use_parent_model_frame>
      </axis>
      <physics>
        <ode>
          <implicit_spring_damper>1</implicit_spring_damper>
          <cfm_damping>1</cfm_damping>
          <limit>
            <cfm>0</cfm>
            <erp>0.2</erp>
          </limit>
        </ode>
      </physics>
    </joint>
    <link name='l_shoulder_3'>
      <pose>-0.01062 -0.109391 0.151746 -3.14159 1.309 0</pose>
      <inertial>
        <pose>0.026798 -1.6e-05 0.014696 0 -0 0</pose>
        <mass>0.35913</mass>
        <inertia>
          <ixx>0.01</ixx>
          <ixy>-2.22441e-07</ixy>
          <ixz>-4.95846e-05</ixz>
          <iyy>0.01</iyy>
          <iyz>1.07538e-07</iyz>
          <izz>0.01</izz>
        </inertia>
      </inertial>
      <collision name='l_shoulder_3_collision'>
        <pose>-0.131901 0 -0.035343 0 -0 0</pose>
        <geometry>
          <mesh>
            <scale>0.001 0.001 0.001</scale>
            <uri>file://iCub/meshes/simmechanics/sim_sea_2-5_l_upper_arm_prt-binary.stl</uri>
          </mesh>
        </geometry>
      </collision>
      <visual name='l_shoulder_3_visual'>
        <pose>-0.131901 0 -0.035343 0 -0 0</pose>
        <geometry>
          <mesh>
            <scale>0.001 0.001 0.001</scale>
            <uri>file://iCub/meshes/simmechanics/sim_sea_2-5_l_upper_arm_prt-binary.stl</uri>
          </mesh>
        </geometry>
        <material>
          <diffuse>1 1 1 1</diffuse>
        </material>
      </visual>
    </link>
    <joint name='l_shoulder_yaw' type='revolute'>
      <child>l_shoulder_3</child>
      <parent>l_shoulder_2</parent>
      <axis>
        <xyz>0.965926 0 0.258819</xyz>
        <limit>
          <lower>-0.645772</lower>
          <upper>1.39626</upper>
          <effort>50000</effort>
          <velocity>50000</velocity>
        </limit>
        <dynamics>
          <damping>1</damping>
          <friction>0</friction>
          <spring_reference>0</spring_reference>
          <spring_stiffness>0</spring_stiffness>
        </dynamics>
        <use_parent_model_frame>0</use_parent_model_frame>
      </axis>
      <physics>
        <ode>
          <implicit_spring_damper>1</implicit_spring_damper>
          <cfm_damping>1</cfm_damping>
          <limit>
            <cfm>0</cfm>
            <erp>0.2</erp>
          </limit>
        </ode>
      </physics>
    </joint>
    <link name='l_upper_arm'>
      <pose>-0.02562 -0.109391 0.095 3.14159 -0 -3.14159</pose>
      <inertial>
        <pose>-0.006121 -0.000189 0.029368 0 -1.309 3.14159</pose>
        <mass>0.746799</mass>
        <inertia>
          <ixx>0.000509731</ixx>
          <ixy>-6.90767e-07</ixy>
          <ixz>1.20048e-05</ixz>
          <iyy>0.00067086</iyy>
          <iyz>3.11833e-06</iyz>
          <izz>0.000601202</izz>
        </inertia>
      </inertial>
      <collision name='l_upper_arm_collision'>
        <pose>-0.015 0 -0.1933 0 -1.309 3.14159</pose>
        <geometry>
          <mesh>
            <scale>0.001 0.001 0.001</scale>
            <uri>file://iCub/meshes/simmechanics/sim_sea_2-5_l_elbow_prt-binary.stl</uri>
          </mesh>
        </geometry>
        <surface>
          <contact>
            <ode/>
          </contact>
          <friction>
            <ode/>
          </friction>
        </surface>
      </collision>
      <visual name='l_upper_arm_visual'>
        <pose>-0.015 0 -0.1933 0 -1.309 3.14159</pose>
        <geometry>
          <mesh>
            <scale>0.001 0.001 0.001</scale>
            <uri>file://iCub/meshes/simmechanics/sim_sea_2-5_l_elbow_prt-binary.stl</uri>
          </mesh>
        </geometry>
        <material>
          <diffuse>1 1 1 1</diffuse>
        </material>
      </visual>
      <velocity_decay/>
    </link>
    <joint name='l_arm_ft_sensor' type='revolute'>
      <child>l_upper_arm</child>
      <parent>l_shoulder_3</parent>
      <axis>
        <limit>
          <lower>0</lower>
          <upper>0</upper>
        </limit>
        <dynamics>
          <damping>0</damping>
          <friction>0</friction>
          <spring_reference>0</spring_reference>
          <spring_stiffness>0</spring_stiffness>
        </dynamics>
        <xyz>0 0 1</xyz>
        <use_parent_model_frame>0</use_parent_model_frame>
      </axis>
      <physics>
        <ode>
          <limit>
            <cfm>0</cfm>
            <erp>0.2</erp>
          </limit>
        </ode>
      </physics>
    </joint>
    <link name='l_elbow_1'>
      <pose>-0.02562 -0.075391 0.01574 -3.14159 1.309 0</pose>
      <inertial>
        <pose>0.006739 0.030302 -0.004658 0 -0 0</pose>
        <mass>0.267903</mass>
        <inertia>
          <ixx>0.01</ixx>
          <ixy>-7.37159e-06</ixy>
          <ixz>1.04505e-05</ixz>
          <iyy>0.01</iyy>
          <iyz>3.9319e-06</iyz>
          <izz>0.01</izz>
        </inertia>
      </inertial>
      <collision name='l_elbow_1_collision'>
        <pose>-0.25939 0.034 -0.085033 0 -0 0</pose>
        <geometry>
          <mesh>
            <scale>0.001 0.001 0.001</scale>
            <uri>file://iCub/meshes/simmechanics/sim_sea_2-5_l_elbow_prosup_prt-binary.stl</uri>
          </mesh>
        </geometry>
      </collision>
      <visual name='l_elbow_1_visual'>
        <pose>-0.25939 0.034 -0.085033 0 -0 0</pose>
        <geometry>
          <mesh>
            <scale>0.001 0.001 0.001</scale>
            <uri>file://iCub/meshes/simmechanics/sim_sea_2-5_l_elbow_prosup_prt-binary.stl</uri>
          </mesh>
        </geometry>
        <material>
          <diffuse>1 1 1 1</diffuse>
        </material>
      </visual>
    </link>
    <joint name='l_elbow' type='revolute'>
      <child>l_elbow_1</child>
      <parent>l_upper_arm</parent>
      <axis>
        <xyz>0 -1 0</xyz>
        <limit>
          <lower>0.261799</lower>
          <upper>1.85005</upper>
          <effort>50000</effort>
          <velocity>50000</velocity>
        </limit>
        <dynamics>
          <damping>1</damping>
          <friction>0</friction>
          <spring_reference>0</spring_reference>
          <spring_stiffness>0</spring_stiffness>
        </dynamics>
        <use_parent_model_frame>0</use_parent_model_frame>
      </axis>
      <physics>
        <ode>
          <implicit_spring_damper>1</implicit_spring_damper>
          <cfm_damping>1</cfm_damping>
          <limit>
            <cfm>0</cfm>
            <erp>0.2</erp>
          </limit>
        </ode>
      </physics>
    </joint>
    <link name='l_forearm'>
      <pose>-0.01062 -0.109391 -0.02006 -3.14159 1.309 0</pose>
      <inertial>
        <pose>0.040451 -0.000686 0.005324 0 -0 0</pose>
        <mass>0.636185</mass>
        <inertia>
          <ixx>0.000371447</ixx>
          <ixy>4.34562e-06</ixy>
          <ixz>-0.000105871</ixz>
          <iyy>0.000674229</iyy>
          <iyz>4.05222e-06</iyz>
          <izz>0.000557115</izz>
        </inertia>
      </inertial>
      <collision name='l_forearm_collision'>
        <pose>-0.296887 0 -0.079551 0 -0 0</pose>
        <geometry>
          <mesh>
            <scale>0.001 0.001 0.001</scale>
            <uri>file://iCub/meshes/simmechanics/sim_sea_2-5_l_forearm_prt-binary.stl</uri>
          </mesh>
        </geometry>
        <surface>
          <contact>
            <ode/>
          </contact>
          <friction>
            <ode/>
          </friction>
        </surface>
      </collision>
      <visual name='l_forearm_visual'>
        <pose>-0.296887 0 -0.079551 0 -0 0</pose>
        <geometry>
          <mesh>
            <scale>0.001 0.001 0.001</scale>
            <uri>file://iCub/meshes/simmechanics/sim_sea_2-5_l_forearm_prt-binary.stl</uri>
          </mesh>
        </geometry>
        <material>
          <diffuse>1 1 1 1</diffuse>
        </material>
      </visual>
    </link>
    <joint name='l_wrist_prosup' type='revolute'>
      <child>l_forearm</child>
      <parent>l_elbow_1</parent>
      <axis>
        <xyz>0.965926 0 0.258819</xyz>
        <limit>
          <lower>-1.0472</lower>
          <upper>1.0472</upper>
          <effort>50000</effort>
          <velocity>50000</velocity>
        </limit>
        <dynamics>
          <damping>1</damping>
          <friction>0</friction>
          <spring_reference>0</spring_reference>
          <spring_stiffness>0</spring_stiffness>
        </dynamics>
        <use_parent_model_frame>0</use_parent_model_frame>
      </axis>
      <physics>
        <ode>
          <implicit_spring_damper>1</implicit_spring_damper>
          <cfm_damping>1</cfm_damping>
          <limit>
            <cfm>0</cfm>
            <erp>0.2</erp>
          </limit>
        </ode>
      </physics>
    </joint>
    <link name='l_wrist_1'>
      <pose>-0.00847 -0.109398 -0.12656 -3.14159 1.309 0</pose>
      <inertial>
        <pose>-0.000981 -0.001178 0.004083 0 -0 0</pose>
        <mass>0.0362152</mass>
        <inertia>
          <ixx>0.01</ixx>
          <ixy>3.08362e-08</ixy>
          <ixz>9.42153e-07</ixz>
          <iyy>0.01</iyy>
          <iyz>-1.58924e-07</iyz>
          <izz>0.01</izz>
        </inertia>
      </inertial>
      <collision name='l_wrist_1_collision'>
        <pose>-0.400315 -7e-06 -0.105038 0 -0 0</pose>
        <geometry>
          <mesh>
            <scale>0.001 0.001 0.001</scale>
            <uri>file://iCub/meshes/simmechanics/sim_sea_2-5_l_wrist_pitch_prt-binary.stl</uri>
          </mesh>
        </geometry>
      </collision>
      <visual name='l_wrist_1_visual'>
        <pose>-0.400315 -7e-06 -0.105038 0 -0 0</pose>
        <geometry>
          <mesh>
            <scale>0.001 0.001 0.001</scale>
            <uri>file://iCub/meshes/simmechanics/sim_sea_2-5_l_wrist_pitch_prt-binary.stl</uri>
          </mesh>
        </geometry>
        <material>
          <diffuse>1 1 1 1</diffuse>
        </material>
      </visual>
    </link>
    <joint name='l_wrist_pitch' type='revolute'>
      <child>l_wrist_1</child>
      <parent>l_forearm</parent>
      <axis>
        <xyz>0.258819 0 -0.965926</xyz>
        <limit>
          <lower>-1.39626</lower>
          <upper>0.436332</upper>
          <effort>50000</effort>
          <velocity>50000</velocity>
        </limit>
        <dynamics>
          <damping>1</damping>
          <friction>0</friction>
          <spring_reference>0</spring_reference>
          <spring_stiffness>0</spring_stiffness>
        </dynamics>
        <use_parent_model_frame>0</use_parent_model_frame>
      </axis>
      <physics>
        <ode>
          <implicit_spring_damper>1</implicit_spring_damper>
          <cfm_damping>1</cfm_damping>
          <limit>
            <cfm>0</cfm>
            <erp>0.2</erp>
          </limit>
        </ode>
      </physics>
    </joint>
    <link name='l_hand'>
      <pose>-0.01092 -0.089898 -0.12656 -3.14159 1.309 0</pose>
      <inertial>
        <pose>0.064768 0.00563 0.02266 0 -0 0</pose>
        <mass>0.247806</mass>
        <inertia>
          <ixx>0.01</ixx>
          <ixy>2.96453e-06</ixy>
          <ixz>-3.68906e-05</ixz>
          <iyy>0.01</iyy>
          <iyz>2.06885e-05</iyz>
          <izz>0.01</izz>
        </inertia>
      </inertial>
      <collision name='l_hand_collision'>
        <pose>-0.39968 0.019493 -0.107405 0 -0 0</pose>
        <geometry>
          <mesh>
            <scale>0.001 0.001 0.001</scale>
            <uri>file://iCub/meshes/simmechanics/sim_sea_2-5_l_hand_prt-binary.stl</uri>
          </mesh>
        </geometry>
      </collision>
      <visual name='l_hand_visual'>
        <pose>-0.39968 0.019493 -0.107405 0 -0 0</pose>
        <geometry>
          <mesh>
            <scale>0.001 0.001 0.001</scale>
            <uri>file://iCub/meshes/simmechanics/sim_sea_2-5_l_hand_prt-binary.stl</uri>
          </mesh>
        </geometry>
        <material>
          <diffuse>1 1 1 1</diffuse>
        </material>
      </visual>
    </link>
    <joint name='l_wrist_yaw' type='revolute'>
      <child>l_hand</child>
      <parent>l_wrist_1</parent>
      <axis>
        <xyz>-0 1 0</xyz>
        <limit>
          <lower>-0.349066</lower>
          <upper>0.436332</upper>
          <effort>50000</effort>
          <velocity>50000</velocity>
        </limit>
        <dynamics>
          <damping>1</damping>
          <friction>0</friction>
          <spring_reference>0</spring_reference>
          <spring_stiffness>0</spring_stiffness>
        </dynamics>
        <use_parent_model_frame>0</use_parent_model_frame>
      </axis>
      <physics>
        <ode>
          <implicit_spring_damper>1</implicit_spring_damper>
          <cfm_damping>1</cfm_damping>
          <limit>
            <cfm>0</cfm>
            <erp>0.2</erp>
          </limit>
        </ode>
      </physics>
    </joint>
    <link name='neck_1'>
      <pose>-0.010809 0.0143 0.254797 1.5708 0 -1.5708</pose>
      <inertial>
        <pose>0.014371 0.006567 -0.006384 0 -0 0</pose>
        <mass>0.125793</mass>
        <inertia>
          <ixx>0.01</ixx>
          <ixy>8.09156e-08</ixy>
          <ixz>-3.74998e-08</ixz>
          <iyy>0.01</iyy>
          <iyz>9.39717e-06</iyz>
          <izz>0.01</izz>
        </inertia>
      </inertial>
      <collision name='neck_1_collision'>
        <pose>0.0143 -0.079997 -0.029501 0 -0 0</pose>
        <geometry>
          <mesh>
            <scale>0.001 0.001 0.001</scale>
            <uri>file://iCub/meshes/simmechanics/sim_sea_2-5_neck_1_prt-binary.stl</uri>
          </mesh>
        </geometry>
      </collision>
      <visual name='neck_1_visual'>
        <pose>0.0143 -0.079997 -0.029501 0 -0 0</pose>
        <geometry>
          <mesh>
            <scale>0.001 0.001 0.001</scale>
            <uri>file://iCub/meshes/simmechanics/sim_sea_2-5_neck_1_prt-binary.stl</uri>
          </mesh>
        </geometry>
        <material>
          <diffuse>1 1 1 1</diffuse>
        </material>
      </visual>
    </link>
    <joint name='neck_pitch' type='revolute'>
      <child>neck_1</child>
      <parent>chest</parent>
      <axis>
        <xyz>-1 0 0</xyz>
        <limit>
          <lower>-0.698132</lower>
          <upper>0.383972</upper>
          <effort>50000</effort>
          <velocity>50000</velocity>
        </limit>
        <dynamics>
          <damping>1</damping>
          <friction>0</friction>
          <spring_reference>0</spring_reference>
          <spring_stiffness>0</spring_stiffness>
        </dynamics>
        <use_parent_model_frame>0</use_parent_model_frame>
      </axis>
      <physics>
        <ode>
          <implicit_spring_damper>1</implicit_spring_damper>
          <cfm_damping>1</cfm_damping>
          <limit>
            <cfm>0</cfm>
            <erp>0.2</erp>
          </limit>
        </ode>
      </physics>
    </joint>
    <link name='neck_2'>
      <pose>-0.031609 0 0.264297 1.5708 0 -1.5708</pose>
      <inertial>
        <pose>-8.9e-05 0.035225 -0.019545 0 -0 0</pose>
        <mass>0.177087</mass>
        <inertia>
          <ixx>0.01</ixx>
          <ixy>-5.25591e-07</ixy>
          <ixz>4.68307e-07</ixz>
          <iyy>0.01</iyy>
          <iyz>9.81476e-06</iyz>
          <izz>0.01</izz>
        </inertia>
      </inertial>
      <collision name='neck_2_collision'>
        <pose>0 -0.089497 -0.050301 0 -0 0</pose>
        <geometry>
          <mesh>
            <scale>0.001 0.001 0.001</scale>
            <uri>file://iCub/meshes/simmechanics/sim_sea_2-5_neck_2_prt-binary.stl</uri>
          </mesh>
        </geometry>
      </collision>
      <visual name='neck_2_visual'>
        <pose>0 -0.089497 -0.050301 0 -0 0</pose>
        <geometry>
          <mesh>
            <scale>0.001 0.001 0.001</scale>
            <uri>file://iCub/meshes/simmechanics/sim_sea_2-5_neck_2_prt-binary.stl</uri>
          </mesh>
        </geometry>
        <material>
          <diffuse>1 1 1 1</diffuse>
        </material>
      </visual>
    </link>
    <joint name='neck_roll' type='revolute'>
      <child>neck_2</child>
      <parent>neck_1</parent>
      <axis>
        <xyz>0 0 1</xyz>
        <limit>
          <lower>-0.349066</lower>
          <upper>0.349066</upper>
          <effort>50000</effort>
          <velocity>50000</velocity>
        </limit>
        <dynamics>
          <damping>1</damping>
          <friction>0</friction>
          <spring_reference>0</spring_reference>
          <spring_stiffness>0</spring_stiffness>
        </dynamics>
        <use_parent_model_frame>0</use_parent_model_frame>
      </axis>
      <physics>
        <ode>
          <implicit_spring_damper>1</implicit_spring_damper>
          <cfm_damping>1</cfm_damping>
          <limit>
            <cfm>0</cfm>
            <erp>0.2</erp>
          </limit>
        </ode>
      </physics>
    </joint>
    <link name='head'>
      <pose>-0.010809 0 0.241953 1.5708 0 -1.5708</pose>
      <inertial>
        <pose>-0.000574 0.113511 -0.007539 0 -0 0</pose>
        <mass>1.50691</mass>
        <inertia>
          <ixx>0.00680478</ixx>
          <ixy>-1.60267e-05</ixy>
          <ixz>7.28166e-05</ixz>
          <iyy>0.00634736</iyy>
          <iyz>0.000292091</iyz>
          <izz>0.00478116</izz>
        </inertia>
      </inertial>
      <collision name='head_collision'>
        <pose>0 -0.067153 -0.029501 0 -0 0</pose>
        <geometry>
          <mesh>
            <scale>0.001 0.001 0.001</scale>
            <uri>file://iCub/meshes/simmechanics/sim_sea_2-5_head_prt-binary.stl</uri>
          </mesh>
        </geometry>
        <surface>
          <contact>
            <ode/>
          </contact>
          <friction>
            <ode/>
          </friction>
        </surface>
      </collision>
      <visual name='head_visual'>
        <pose>0 -0.067153 -0.029501 0 -0 0</pose>
        <geometry>
          <mesh>
            <scale>0.001 0.001 0.001</scale>
            <uri>file://iCub/meshes/simmechanics/sim_sea_2-5_head_prt-binary.stl</uri>
          </mesh>
        </geometry>
        <material>
          <diffuse>1 1 1 1</diffuse>
        </material>
      </visual>
      <gravity>1</gravity>
      <velocity_decay/>
    </link>
    <joint name='neck_yaw' type='revolute'>
      <child>head</child>
      <parent>neck_2</parent>
      <axis>
        <xyz>0 1 0</xyz>
        <limit>
          <lower>-0.872665</lower>
          <upper>0.872665</upper>
          <effort>50000</effort>
          <velocity>50000</velocity>
        </limit>
        <dynamics>
          <damping>1</damping>
          <friction>0</friction>
          <spring_reference>0</spring_reference>
          <spring_stiffness>0</spring_stiffness>
        </dynamics>
        <use_parent_model_frame>0</use_parent_model_frame>
      </axis>
      <physics>
        <ode>
          <implicit_spring_damper>1</implicit_spring_damper>
          <cfm_damping>1</cfm_damping>
          <limit>
            <cfm>0</cfm>
            <erp>0.2</erp>
          </limit>
        </ode>
      </physics>
    </joint>
    <link name='r_shoulder_1'>
      <pose>-0.013467 0.120016 0.1748 -1.5708 0 2.0944</pose>
      <inertial>
        <pose>-0.012266 3.2e-05 -0.003211 0 -0 0</pose>
        <mass>0.114862</mass>
        <inertia>
          <ixx>0.01</ixx>
          <ixy>-1.65173e-08</ixy>
          <ixz>-3.55626e-06</ixz>
          <iyy>0.01</iyy>
          <iyz>-6.13337e-08</iyz>
          <izz>0.01</izz>
        </inertia>
      </inertial>
      <collision name='r_shoulder_1_collision'>
        <pose>0.099008 0 -0.026529 0 -0 0</pose>
        <geometry>
          <mesh>
            <scale>0.001 0.001 0.001</scale>
            <uri>file://iCub/meshes/simmechanics/sim_sea_2-5_r_shoulder_1_prt-binary.stl</uri>
          </mesh>
        </geometry>
      </collision>
      <visual name='r_shoulder_1_visual'>
        <pose>0.099008 0 -0.026529 0 -0 0</pose>
        <geometry>
          <mesh>
            <scale>0.001 0.001 0.001</scale>
            <uri>file://iCub/meshes/simmechanics/sim_sea_2-5_r_shoulder_1_prt-binary.stl</uri>
          </mesh>
        </geometry>
        <material>
          <diffuse>1 1 1 1</diffuse>
        </material>
      </visual>
    </link>
    <joint name='r_shoulder_pitch' type='revolute'>
      <child>r_shoulder_1</child>
      <parent>chest</parent>
      <axis>
        <xyz>-0.965926 0 0.258819</xyz>
        <limit>
          <lower>-1.66679</lower>
          <upper>0.174533</upper>
          <effort>50000</effort>
          <velocity>50000</velocity>
        </limit>
        <dynamics>
          <damping>1</damping>
          <friction>0</friction>
          <spring_reference>0</spring_reference>
          <spring_stiffness>0</spring_stiffness>
        </dynamics>
        <use_parent_model_frame>0</use_parent_model_frame>
      </axis>
      <physics>
        <ode>
          <implicit_spring_damper>1</implicit_spring_damper>
          <cfm_damping>1</cfm_damping>
          <limit>
            <cfm>0</cfm>
            <erp>0.2</erp>
          </limit>
        </ode>
      </physics>
    </joint>
    <link name='r_shoulder_2'>
      <pose>-0.021983 0.106346 0.1748 -3.14159 -1.309 -2.87979</pose>
      <inertial>
        <pose>-0.021414 0.000272 -0.01944 0 -0 0</pose>
        <mass>0.238162</mass>
        <inertia>
          <ixx>0.01</ixx>
          <ixy>-1.12091e-07</ixy>
          <ixz>1.02574e-05</ixz>
          <iyy>0.01</iyy>
          <iyz>1.19785e-06</iyz>
          <izz>0.01</izz>
        </inertia>
      </inertial>
      <collision name='r_shoulder_2_collision'>
        <pose>0.106588 0 -0.040739 0 -0 0</pose>
        <geometry>
          <mesh>
            <scale>0.001 0.001 0.001</scale>
            <uri>file://iCub/meshes/simmechanics/sim_sea_2-5_r_shoulder_2_prt-binary.stl</uri>
          </mesh>
        </geometry>
      </collision>
      <visual name='r_shoulder_2_visual'>
        <pose>0.106588 0 -0.040739 0 -0 0</pose>
        <geometry>
          <mesh>
            <scale>0.001 0.001 0.001</scale>
            <uri>file://iCub/meshes/simmechanics/sim_sea_2-5_r_shoulder_2_prt-binary.stl</uri>
          </mesh>
        </geometry>
        <material>
          <diffuse>1 1 1 1</diffuse>
        </material>
      </visual>
    </link>
    <joint name='r_shoulder_roll' type='revolute'>
      <child>r_shoulder_2</child>
      <parent>r_shoulder_1</parent>
      <axis>
        <xyz>-0.258819 -0 -0.965926</xyz>
        <limit>
          <lower>0</lower>
          <upper>2.80649</upper>
          <effort>50000</effort>
          <velocity>50000</velocity>
        </limit>
        <dynamics>
          <damping>1</damping>
          <friction>0</friction>
          <spring_reference>0</spring_reference>
          <spring_stiffness>0</spring_stiffness>
        </dynamics>
        <use_parent_model_frame>0</use_parent_model_frame>
      </axis>
      <physics>
        <ode>
          <implicit_spring_damper>1</implicit_spring_damper>
          <cfm_damping>1</cfm_damping>
          <limit>
            <cfm>0</cfm>
            <erp>0.2</erp>
          </limit>
        </ode>
      </physics>
    </joint>
    <link name='r_shoulder_3'>
      <pose>-0.01062 0.109391 0.151712 -3.14159 -1.309 -3.14159</pose>
      <inertial>
        <pose>-0.026762 -7e-06 0.0147 0 -0 0</pose>
        <mass>0.35913</mass>
        <inertia>
          <ixx>0.01</ixx>
          <ixy>3.60361e-07</ixy>
          <ixz>4.94445e-05</ixz>
          <iyy>0.01</iyy>
          <iyz>2.65919e-07</iyz>
          <izz>0.01</izz>
        </inertia>
      </inertial>
      <collision name='r_shoulder_3_collision'>
        <pose>0.131934 0 -0.035352 0 -0 0</pose>
        <geometry>
          <mesh>
            <scale>0.001 0.001 0.001</scale>
            <uri>file://iCub/meshes/simmechanics/sim_sea_2-5_r_upper_arm_prt-binary.stl</uri>
          </mesh>
        </geometry>
      </collision>
      <visual name='r_shoulder_3_visual'>
        <pose>0.131934 0 -0.035352 0 -0 0</pose>
        <geometry>
          <mesh>
            <scale>0.001 0.001 0.001</scale>
            <uri>file://iCub/meshes/simmechanics/sim_sea_2-5_r_upper_arm_prt-binary.stl</uri>
          </mesh>
        </geometry>
        <material>
          <diffuse>1 1 1 1</diffuse>
        </material>
      </visual>
    </link>
    <joint name='r_shoulder_yaw' type='revolute'>
      <child>r_shoulder_3</child>
      <parent>r_shoulder_2</parent>
      <axis>
        <xyz>0.965926 -0 -0.258819</xyz>
        <limit>
          <lower>-0.645772</lower>
          <upper>1.39626</upper>
          <effort>50000</effort>
          <velocity>50000</velocity>
        </limit>
        <dynamics>
          <damping>1</damping>
          <friction>0</friction>
          <spring_reference>0</spring_reference>
          <spring_stiffness>0</spring_stiffness>
        </dynamics>
        <use_parent_model_frame>0</use_parent_model_frame>
      </axis>
      <physics>
        <ode>
          <implicit_spring_damper>1</implicit_spring_damper>
          <cfm_damping>1</cfm_damping>
          <limit>
            <cfm>0</cfm>
            <erp>0.2</erp>
          </limit>
        </ode>
      </physics>
    </joint>
    <link name='r_upper_arm'>
      <pose>-0.02562 0.109391 0.095 -3.14159 -0 -3.14159</pose>
      <inertial>
        <pose>-0.006087 0.000126 0.029312 0 1.309 0</pose>
        <mass>0.745104</mass>
        <inertia>
          <ixx>0.000509527</ixx>
          <ixy>1.19292e-06</ixy>
          <ixz>-1.17426e-05</ixz>
          <iyy>0.000668487</iyy>
          <iyz>1.13363e-06</iyz>
          <izz>0.000599254</izz>
        </inertia>
      </inertial>
      <collision name='r_upper_arm_collision'>
        <pose>-0.015 0 -0.1933 0 1.309 0</pose>
        <geometry>
          <mesh>
            <scale>0.001 0.001 0.001</scale>
            <uri>file://iCub/meshes/simmechanics/sim_sea_2-5_r_elbow_prt-binary.stl</uri>
          </mesh>
        </geometry>
        <surface>
          <contact>
            <ode/>
          </contact>
          <friction>
            <ode/>
          </friction>
        </surface>
      </collision>
      <visual name='r_upper_arm_visual'>
        <pose>-0.015 0 -0.1933 0 1.309 0</pose>
        <geometry>
          <mesh>
            <scale>0.001 0.001 0.001</scale>
            <uri>file://iCub/meshes/simmechanics/sim_sea_2-5_r_elbow_prt-binary.stl</uri>
          </mesh>
        </geometry>
        <material>
          <diffuse>1 1 1 1</diffuse>
        </material>
      </visual>
    </link>
    <joint name='r_arm_ft_sensor' type='revolute'>
      <child>r_upper_arm</child>
      <parent>r_shoulder_3</parent>
      <axis>
        <limit>
          <lower>0</lower>
          <upper>0</upper>
        </limit>
        <dynamics>
          <damping>0</damping>
          <friction>0</friction>
          <spring_reference>0</spring_reference>
          <spring_stiffness>0</spring_stiffness>
        </dynamics>
        <xyz>0 0 1</xyz>
        <use_parent_model_frame>0</use_parent_model_frame>
      </axis>
      <physics>
        <ode>
          <limit>
            <cfm>0</cfm>
            <erp>0.2</erp>
          </limit>
        </ode>
      </physics>
    </joint>
    <link name='r_elbow_1'>
      <pose>-0.02562 0.086891 0.01574 -3.14159 -1.309 -3.14159</pose>
      <inertial>
        <pose>-0.006739 0.018802 -0.004658 0 -0 0</pose>
        <mass>0.267903</mass>
        <inertia>
          <ixx>0.01</ixx>
          <ixy>7.36974e-06</ixy>
          <ixz>-1.04536e-05</ixz>
          <iyy>0.01</iyy>
          <iyz>3.92498e-06</iyz>
          <izz>0.01</izz>
        </inertia>
      </inertial>
      <collision name='r_elbow_1_collision'>
        <pose>0.25939 0.0225 -0.085033 0 -0 0</pose>
        <geometry>
          <mesh>
            <scale>0.001 0.001 0.001</scale>
            <uri>file://iCub/meshes/simmechanics/sim_sea_2-5_r_elbow_prosup_prt-binary.stl</uri>
          </mesh>
        </geometry>
      </collision>
      <visual name='r_elbow_1_visual'>
        <pose>0.25939 0.0225 -0.085033 0 -0 0</pose>
        <geometry>
          <mesh>
            <scale>0.001 0.001 0.001</scale>
            <uri>file://iCub/meshes/simmechanics/sim_sea_2-5_r_elbow_prosup_prt-binary.stl</uri>
          </mesh>
        </geometry>
        <material>
          <diffuse>1 1 1 1</diffuse>
        </material>
      </visual>
    </link>
    <joint name='r_elbow' type='revolute'>
      <child>r_elbow_1</child>
      <parent>r_upper_arm</parent>
      <axis>
        <xyz>0 1 0</xyz>
        <limit>
          <lower>0.261799</lower>
          <upper>1.85005</upper>
          <effort>50000</effort>
          <velocity>50000</velocity>
        </limit>
        <dynamics>
          <damping>1</damping>
          <friction>0</friction>
          <spring_reference>0</spring_reference>
          <spring_stiffness>0</spring_stiffness>
        </dynamics>
        <use_parent_model_frame>0</use_parent_model_frame>
      </axis>
      <physics>
        <ode>
          <implicit_spring_damper>1</implicit_spring_damper>
          <cfm_damping>1</cfm_damping>
          <limit>
            <cfm>0</cfm>
            <erp>0.2</erp>
          </limit>
        </ode>
      </physics>
    </joint>
    <link name='r_forearm'>
      <pose>-0.01062 0.109391 -0.02006 -3.14159 -1.309 -3.14159</pose>
      <inertial>
        <pose>-0.040439 -0.000328 0.005327 0 -0 0</pose>
        <mass>0.6347</mass>
        <inertia>
          <ixx>0.000370044</ixx>
          <ixy>-1.65419e-06</ixy>
          <ixz>0.00010538</ixz>
          <iyy>0.000672279</iyy>
          <iyz>1.1456e-06</iyz>
          <izz>0.000553637</izz>
        </inertia>
      </inertial>
      <collision name='r_forearm_collision'>
        <pose>0.296887 0 -0.079551 0 -0 0</pose>
        <geometry>
          <mesh>
            <scale>0.001 0.001 0.001</scale>
            <uri>file://iCub/meshes/simmechanics/sim_sea_2-5_r_forearm_prt-binary.stl</uri>
          </mesh>
        </geometry>
        <surface>
          <contact>
            <ode/>
          </contact>
          <friction>
            <ode/>
          </friction>
        </surface>
      </collision>
      <visual name='r_forearm_visual'>
        <pose>0.296887 0 -0.079551 0 -0 0</pose>
        <geometry>
          <mesh>
            <scale>0.001 0.001 0.001</scale>
            <uri>file://iCub/meshes/simmechanics/sim_sea_2-5_r_forearm_prt-binary.stl</uri>
          </mesh>
        </geometry>
        <material>
          <diffuse>1 1 1 1</diffuse>
        </material>
      </visual>
      <velocity_decay/>
    </link>
    <joint name='r_wrist_prosup' type='revolute'>
      <child>r_forearm</child>
      <parent>r_elbow_1</parent>
      <axis>
        <xyz>0.965926 -0 -0.258819</xyz>
        <limit>
          <lower>-1.0472</lower>
          <upper>1.0472</upper>
          <effort>50000</effort>
          <velocity>50000</velocity>
        </limit>
        <dynamics>
          <damping>1</damping>
          <friction>0</friction>
          <spring_reference>0</spring_reference>
          <spring_stiffness>0</spring_stiffness>
        </dynamics>
        <use_parent_model_frame>0</use_parent_model_frame>
      </axis>
      <physics>
        <ode>
          <implicit_spring_damper>1</implicit_spring_damper>
          <cfm_damping>1</cfm_damping>
          <limit>
            <cfm>0</cfm>
            <erp>0.2</erp>
          </limit>
        </ode>
      </physics>
    </joint>
    <link name='r_wrist_1'>
      <pose>-0.00817 0.109398 -0.12656 -3.14159 -1.309 -3.14159</pose>
      <inertial>
        <pose>0.000986 -0.001176 0.004101 0 -0 0</pose>
        <mass>0.0362615</mass>
        <inertia>
          <ixx>0.01</ixx>
          <ixy>-3.10462e-08</ixy>
          <ixz>-9.44554e-07</ixz>
          <iyy>0.01</iyy>
          <iyz>-1.59685e-07</iyz>
          <izz>0.01</izz>
        </inertia>
      </inertial>
      <collision name='r_wrist_1_collision'>
        <pose>0.400392 -7e-06 -0.104748 0 -0 0</pose>
        <geometry>
          <mesh>
            <scale>0.001 0.001 0.001</scale>
            <uri>file://iCub/meshes/simmechanics/sim_sea_2-5_r_wrist_pitch_prt-binary.stl</uri>
          </mesh>
        </geometry>
      </collision>
      <visual name='r_wrist_1_visual'>
        <pose>0.400392 -7e-06 -0.104748 0 -0 0</pose>
        <geometry>
          <mesh>
            <scale>0.001 0.001 0.001</scale>
            <uri>file://iCub/meshes/simmechanics/sim_sea_2-5_r_wrist_pitch_prt-binary.stl</uri>
          </mesh>
        </geometry>
        <material>
          <diffuse>1 1 1 1</diffuse>
        </material>
      </visual>
    </link>
    <joint name='r_wrist_pitch' type='revolute'>
      <child>r_wrist_1</child>
      <parent>r_forearm</parent>
      <axis>
        <xyz>0.258819 0 0.965926</xyz>
        <limit>
          <lower>-1.39626</lower>
          <upper>0.436332</upper>
          <effort>50000</effort>
          <velocity>50000</velocity>
        </limit>
        <dynamics>
          <damping>1</damping>
          <friction>0</friction>
          <spring_reference>0</spring_reference>
          <spring_stiffness>0</spring_stiffness>
        </dynamics>
        <use_parent_model_frame>0</use_parent_model_frame>
      </axis>
      <physics>
        <ode>
          <implicit_spring_damper>1</implicit_spring_damper>
          <cfm_damping>1</cfm_damping>
          <limit>
            <cfm>0</cfm>
            <erp>0.2</erp>
          </limit>
        </ode>
      </physics>
    </joint>
    <link name='r_hand'>
      <pose>-0.01062 0.089898 -0.12656 -3.14159 -1.309 -3.14159</pose>
      <inertial>
        <pose>-0.064668 0.0056 0.022681 0 -0 0</pose>
        <mass>0.248289</mass>
        <inertia>
          <ixx>0.01</ixx>
          <ixy>-2.3536e-06</ixy>
          <ixz>3.61526e-05</ixz>
          <iyy>0.01</iyy>
          <iyz>2.07146e-05</iyz>
          <izz>0.01</izz>
        </inertia>
      </inertial>
      <collision name='r_hand_collision'>
        <pose>0.399758 0.019493 -0.107115 0 -0 0</pose>
        <geometry>
          <mesh>
            <scale>0.001 0.001 0.001</scale>
            <uri>file://iCub/meshes/simmechanics/sim_sea_2-5_r_hand_prt-binary.stl</uri>
          </mesh>
        </geometry>
      </collision>
      <visual name='r_hand_visual'>
        <pose>0.399758 0.019493 -0.107115 0 -0 0</pose>
        <geometry>
          <mesh>
            <scale>0.001 0.001 0.001</scale>
            <uri>file://iCub/meshes/simmechanics/sim_sea_2-5_r_hand_prt-binary.stl</uri>
          </mesh>
        </geometry>
        <material>
          <diffuse>1 1 1 1</diffuse>
        </material>
      </visual>
    </link>
    <joint name='r_wrist_yaw' type='revolute'>
      <child>r_hand</child>
      <parent>r_wrist_1</parent>
      <axis>
        <xyz>0 1 0</xyz>
        <limit>
          <lower>-0.349066</lower>
          <upper>0.436332</upper>
          <effort>50000</effort>
          <velocity>50000</velocity>
        </limit>
        <dynamics>
          <damping>1</damping>
          <friction>0</friction>
          <spring_reference>0</spring_reference>
          <spring_stiffness>0</spring_stiffness>
        </dynamics>
        <use_parent_model_frame>0</use_parent_model_frame>
      </axis>
      <physics>
        <ode>
          <implicit_spring_damper>1</implicit_spring_damper>
          <cfm_damping>1</cfm_damping>
          <limit>
            <cfm>0</cfm>
            <erp>0.2</erp>
          </limit>
        </ode>
      </physics>
    </joint>
    <static>0</static>
    <pose>0 0 0.63 0 -0 3.14</pose>
  </model>
</sdf>
